Workbook

Sheet Panduan_Mahasiswa
B1: Panduan Self-Assessment UTS untuk Mahasiswa
B2: Manajemen Proyek Sistem Informasi · SIB 3G · Artefak Notion Minggu 1–7 + Laporan Tengah Semester & Presentasi
B4: Intinya
B5: Untuk UTS, kelompok kalian melaporkan 10 artefak: 8 artefak Notion dari Minggu 1–7, ditambah Laporan Tengah Semester (LTS) dan slide presentasinya. Setiap artefak diubah ke PDF, diunggah ke Google Drive, lalu link-nya diisi di sheet kelompok kalian. Dosen akan membuka setiap PDF untuk memeriksa. Nilai dihitung dari hasil pemeriksaan dosen, bukan dari klaim kalian.
B7: 5 langkah pengumpulan (tenggat: H-1 UTS)
B8: No | C8: Langkah | D8: Yang dilakukan
B9: 1 | C9: Ekspor ke PDF | D9: Ekspor setiap artefak Notion ke PDF (ikuti tabel 'Cara ekspor' di bawah, terutama WBS dan Jadwal). Susun LTS dengan Template & Panduan LTS, lalu simpan LTS dan slide presentasinya sebagai PDF.
B10: 2 | C10: Cek PDF-nya | D10: Buka sendiri file PDF-nya. Pastikan semua isi terlihat: toggle terbuka, kolom tabel tidak terpotong, tidak ada halaman kosong. Yang dinilai adalah apa yang terlihat di PDF.
B11: 3 | C11: Unggah ke GDrive | D11: Simpan semua PDF di satu folder: PBL_SIB3G_Kel[nomor]/Snapshot_UTS/. Beri nama file sesuai kolom 'Nama file' (contoh: M06b_WBS.pdf).
B12: 4 | C12: Atur akses & salin link | D12: Klik kanan file → Bagikan → Akses umum: 'Siapa saja yang memiliki link' sebagai Pelihat. Salin link FILE, bukan link folder.
B13: 5 | C13: Isi sheet kelompok | D13: Buka sheet kelompok kalian (Kel1–Kel5), isi kolom kuning saja: Level klaim, Link PDF, PIC, dan Catatan. Link Notion boleh diisi sebagai tambahan (tidak wajib).
B15: Cara ekspor & nama file per artefak
B16: Kode | C16: Artefak | D16: Cara ekspor ke PDF | E16: Nama file
B17: M01 | C17: Workspace Notion kelompok & topik proyek | D17: Buka page beranda workspace → ••• (pojok kanan atas) → Export → format PDF → Export. | E17: M01_Workspace.pdf
B18: M02 | C18: Problem Statement & Business Case | D18: Ekspor page seperti biasa (••• → Export → PDF). | E18: M02_BusinessCase.pdf
B19: M03 | C19: Stakeholder Register & Engagement Plan | D19: Buka database dalam tampilan Table, lalu ekspor ke PDF. Cek semua kolom terlihat; jika terpotong, perkecil skala di jendela Export lalu ekspor ulang. | E19: M03_StakeholderRegister.pdf
B20: M05 | C20: Project Charter | D20: Ekspor page seperti biasa. | E20: M05_ProjectCharter.pdf
B21: M06a | C21: Scope Statement | D21: Ekspor page seperti biasa. | E21: M06a_ScopeStatement.pdf
B22: M06b | C22: Work Breakdown Structure | D22: BUKA SEMUA TOGGLE terlebih dahulu sampai level terbawah terlihat, baru ekspor ke PDF. Cek PDF: ketiga level harus tampak. | E22: M06b_WBS.pdf
B23: M06c | C23: Model Kebutuhan (Use Case) | D23: Ekspor page seperti biasa. | E23: M06c_UseCase.pdf
B24: M07 | C24: Jadwal Proyek (Timeline/Gantt) | D24: Satu PDF berisi: (1) screenshot tampilan Table (Task, Start, End, Depends On), (2) screenshot tampilan Timeline, (3) catatan jalur kritis. Cara mudah: tempel ketiganya di Google Docs → File → Download → PDF. | E24: M07_JadwalProyek.pdf
B25: M08a | C25: Laporan Tengah Semester (LTS) | D25: Isi Template_Laporan_Tengah_Semester_ManproSI.docx sesuai Panduan LTS → File → Save as / Download → PDF. | E25: M08a_LaporanTengahSemester.pdf
B26: M08b | C26: Slide Presentasi LTS | D26: Ekspor slide ke PDF (File → Download/Export → PDF). | E26: M08b_PresentasiLTS.pdf
B27: Baris oranye = perlu perhatian khusus saat ekspor.
B29: Cara menentukan Level klaim (0–4)
B30: Level | C30: Artinya | D30: Contoh
B31: 0 | C31: Belum ada | D31: Artefak belum dibuat, atau PDF tidak bisa dibuka.
B32: 1 | C32: Baru dibuat | D32: Page/database sudah ada, tapi isinya sebagian besar masih kosong.
B33: 2 | C33: Sebagian | D33: Baru sebagian langkah jobsheet yang dikerjakan. Contoh: WBS baru sampai level 2.
B34: 3 | C34: Lengkap | D34: Semua langkah jobsheet sudah dikerjakan untuk proyek kalian sendiri, sesuai kriteria penilaian di jobsheet.
B35: 4 | C35: Lengkap & sudah direvisi | D35: Level 3, ditambah sudah diperbaiki sesuai masukan dosen, dan nyambung dengan artefak sesudahnya (mis. isi WBS sama dengan task di Jadwal).
B37: Penting
B38: • Isi level dengan jujur. Jika level klaim kalian lebih tinggi 2 level atau lebih dari hasil pemeriksaan dosen, baris itu ditandai 'Overclaim' dan akan dibahas saat presentasi UTS.
B39: • Otomatis level 0 jika: link kosong, link tidak bisa dibuka, salah file, PDF kosong, atau isinya menyalin contoh PT Kreasi Digital.
B40: • Jangan mengubah kolom selain kolom kuning. Kolom biru diisi dosen.
B42: Contoh pengisian satu baris
C43: Kolom | D43: Contoh isi
C44: Kode / Artefak | D44: M06b – Work Breakdown Structure
C45: Level klaim | D45: 3
C46: Link PDF (GDrive) | D46: https://drive.google.com/file/d/…/view
...

Sheet Panduan_Dosen
B1: Panduan Dosen – Verifikasi & Perhitungan Nilai UTS
B2: Sheet ini tidak perlu dibaca mahasiswa. Sel kuning dapat diubah.
B4: 1. Langkah verifikasi
B5: Buka PDF | D5: Untuk tiap baris, buka link PDF. Bandingkan isinya dengan kolom 'Kriteria lengkap' di sheet Peta_Artefak (diambil dari bagian F jobsheet).
B6: Isi kolom biru | D6: Link valid (Ya/Tidak), Level terverifikasi (0–4), dan Komentar singkat. 'Tidak' otomatis menjadikan level dihitung = 0.
B7: Skor rubrik | D7: Isi skor 1–5 untuk tiap aspek Rubrik LTS (setelah membaca M08a) dan Rubrik Presentasi (saat presentasi) di bagian Ringkasan tiap sheet kelompok.
B8: Cek tanggal | D8: Bila perlu, cek tanggal unggah/ubah file di GDrive (Detail file) untuk memastikan PDF diunggah sebelum tenggat.
B10: 2. Logika perhitungan (earned value sederhana)
B11: Capaian (EV) | D11: Σ(bobot × level terverifikasi ÷ 4). 100% = semua artefak M1–M7 di level 4.
B12: Target Minggu 8 (PV) | D12: Σ(bobot × target level ÷ 4). Target bawaan: M1–M5 level 4 (sudah sempat direvisi), M6–M8 level 3 (baru dikumpulkan) → 84,75%.
B13: SPI | D13: Capaian ÷ Target. Menentukan status dan komponen progres nilai.
B14: Porsi M1–M7 dari seluruh proyek | C14: 0.48 | D14: Dipakai untuk baris 'Setara progres proyek keseluruhan' (artefak M9–M16 ≈ 52% sisanya).
B16: 3. Komponen Nilai UTS
B17: Komponen | C17: Bobot | D17: Cara menghitung
B18: Capaian artefak (terverifikasi, termasuk LTS & slide) | C18: 0.5 | D18: MIN(SPI;1) × 100
B19: Kualitas Laporan Tengah Semester | C19: 0.3 | D19: Rubrik LTS (bagian 5): Σ(skor × bobot) ÷ 5 × 100
B20: Presentasi LTS | C20: 0.2 | D20: Rubrik Presentasi (bagian 6): Σ(skor × bobot) ÷ 5 × 100
B21: Total bobot | C21: =SUM(C18:C20) -> 1
B23: 4. Ambang status (SPI)
B24: Status | C24: SPI minimal | D24: Makna
B25: On Track | C25: 0.95 | D25: Sesuai/melampaui target Minggu 8.
B26: Perlu Perhatian | C26: 0.8 | D26: Tertinggal sedikit; wajib rencana pemulihan sebelum Kuis 2 (Minggu 12).
B27: Kritis | C27: 0 | D27: Tertinggal jauh; perlu pendampingan & penjadwalan ulang.
B29: 5. Rubrik Laporan Tengah Semester (M08a)
B30: Aspek | C30: Bobot | D30: Skor 1 | Skor 3 | Skor 5
B31: Ringkasan (B) | C31: 0.1 | D31: 1: Tidak ada / umum tanpa angka | 3: Tujuan & capaian ada, tanpa angka/status | 5: ≤300 kata, lengkap dengan angka capaian, status, fokus berikutnya
B32: Hasil pelaksanaan (C.1–C.5) | C32: 0.25 | D32: 1: Salin-tempel Notion / tidak sesuai artefak | 3: Ringkas, ada artefak yang tidak dibahas | 5: Semua artefak diringkas tajam, dirujuk ke lampiran
B33: Status & interpretasi capaian (C.6, C.7, E) | C33: 0.2 | D33: 1: Tanpa angka / tidak sesuai self-assessment | 3: Angka ada, interpretasi dangkal | 5: Angka konsisten, deliverable bertabel dengan bukti, interpretasi jujur
B34: Keterlibatan stakeholder (D) | C34: 0.1 | D34: 1: Tidak diisi | 3: Ada kegiatan, tanpa tindak lanjut | 5: Kegiatan, masukan, dan tindak lanjut jelas
B35: Kendala (F) | C35: 0.15 | D35: 1: Tidak ada / umum | 3: Spesifik, tidak dikaitkan risiko awal | 5: Spesifik, dikaitkan risiko M02, ada penanganan
B36: Rencana berikutnya (G) | C36: 0.15 | D36: 1: Tidak ada | 3: Kegiatan tanpa minggu/PIC | 5: Minggu, output, PIC lengkap; selaras M07; rencana pemulihan bila perlu
B37: Konsistensi & kerapian | C37: 0.05 | D37: 1: Banyak inkonsistensi | 3: Sedikit inkonsistensi | 5: Konsisten, rapi, link lampiran valid
B38: Total bobot | C38: =SUM(C31:C37) -> 1
B40: 6. Rubrik Presentasi LTS (M08b)
B41: Aspek | C41: Bobot | D41: Skor 1 | Skor 3 | Skor 5
B42: Struktur & pengelolaan waktu | C42: 0.25 | D42: 1: Tidak runtut, jauh melewati waktu | 3: Runtut, sedikit melewati waktu | 5: Runtut, tepat 10 menit, slide jelas
B43: Akurasi status (rencana vs realisasi) | C43: 0.25 | D43: 1: Hanya menceritakan yang dikerjakan | 3: % capaian tanpa perbandingan target | 5: % capaian, target, SPI, status dijelaskan benar
B44: Analisis kendala & rencana pemulihan | C44: 0.25 | D44: 1: Tidak dibahas | 3: Kendala disebut, rencana umum | 5: Kendala dianalisis, pemulihan konkret & realistis
B45: Penguasaan & partisipasi tim | C45: 0.25 | D45: 1: Satu orang mendominasi, tidak bisa menjawab | 3: Semua bicara, sebagian bisa menjawab | 5: Semua bicara dan mampu menjawab
B46: Total bobot | C46: =SUM(C42:C45) -> 1
...

Sheet Peta_Artefak
A1: Peta Artefak UTS (Output Jobsheet Notion Minggu 1–7) – Kriteria, Bobot & Target Minggu 8
A2: Kolom Kriteria membantu mahasiswa menentukan level; Bobot dan Target (sel kuning) diatur dosen. Total bobot = 100.
A4: No | B4: Minggu | C4: Kode | D4: Artefak Notion | E4: Bentuk di Notion | F4: Domain PMBOK 8 | G4: Kriteria lengkap (dari jobsheet) | H4: Bobot | I4: Target Minggu 8 (0–4)
A5: 1 | B5: 1 | C5: M01 | D5: Workspace Notion kelompok & topik proyek | E5: Page beranda | F5: Overview / Governance | G5: Workspace dibuat, topik proyek & anggota tim tercantum, semua page artefak tertaut dari beranda. | H5: 4 | I5: 4
A6: 2 | B6: 2 | C6: M02 | D6: Problem Statement & Business Case | E6: Page | F6: Governance + Risk (pengantar) | G6: Problem statement spesifik (40%) · business case & value proposition terhubung ke masalah (35%) · governance sederhana + min. 2 risiko awal (25%). | H6: 11 | I6: 4
A7: 3 | B7: 3 | C7: M03 | D7: Stakeholder Register & Engagement Plan | E7: Database | F7: Stakeholders | G7: Min. 5 stakeholder termasuk yang tidak langsung (35%) · power-interest & kuadran masuk akal (35%) · strategi & frekuensi komunikasi sesuai kuadran (30%). | H7: 11 | I7: 4
A8: 4 | B8: 5 | C8: M05 | D8: Project Charter | E8: Page | F8: Tailoring + Governance | G8: Pendekatan predictive/adaptive/hybrid beralasan (25%) · tujuan, scope garis besar, tim & peran, milestone, asumsi/risiko lengkap (50%) · kesepakatan kerja tim jelas (25%). | H8: 13 | I8: 4
A9: 5 | B9: 6 | C9: M06a | D9: Scope Statement | E9: Page | F9: Scope | G9: Justification, deliverables, acceptance criteria, exclusions, constraints (aspek 30% jobsheet M6). | H9: 11 | I9: 3
A10: 6 | B10: 6 | C10: M06b | D10: Work Breakdown Structure | E10: Page (toggle list) | F10: Scope | G10: Min. 3 level, mencakup seluruh deliverable di Scope Statement (aspek 40% jobsheet M6). | H10: 15 | I10: 3
A11: 7 | B11: 6 | C11: M06c | D11: Model Kebutuhan (Use Case) | E11: Page | F11: Scope (model kebutuhan, khas SI) | G11: Aktor & use case jelas dan sesuai deliverable (aspek 30% jobsheet M6). | H11: 10 | I11: 3
A12: 8 | B12: 7 | C12: M07 | D12: Jadwal Proyek (Timeline/Gantt) | E12: Database + Timeline view | F12: Schedule | G12: Semua work package WBS masuk jadwal dengan durasi wajar (35%) · dependensi logis (35%) · catatan jalur kritis & alasannya (30%). | H12: 15 | I12: 3
A13: 9 | B13: 8 | C13: M08a | D13: Laporan Tengah Semester (LTS) | E13: Dokumen (template .docx) | F13: Governance (status report / M&C) | G13: Mengikuti Template LTS bagian A–H; angka status konsisten dengan self-assessment; dinilai rinci dengan Rubrik LTS di Panduan_Dosen. | H13: 7 | I13: 3
A14: 10 | B14: 8 | C14: M08b | D14: Slide Presentasi LTS | E14: Slide (PPT/Google Slides/Canva) | F14: Stakeholders (komunikasi) | G14: 8–10 slide mengikuti struktur di Panduan LTS bagian 4; dinilai saat presentasi dengan Rubrik Presentasi. | H14: 3 | I14: 3
G15: Total bobot | H15: =SUM(H5:H14) -> 100
G16: Target capaian Minggu 8 | I16: =SUMPRODUCT(H5:H14,I5:I14)/400 -> 0.8475

Sheet Kel1
A1: Self-Assessment UTS – Artefak Proyek (Minggu 1–8)
A2: Kelompok | D2: Kel. 1 (Nafisa dkk.)
A3: Topik | D3: REBANT – pesanan, produksi MTS/MTO & persediaan
A4: Link folder GDrive Snapshot_UTS
A5: Petunjuk | D5: Isi kolom kuning saja. Cara pengisian ada di sheet Panduan_Mahasiswa.
A7: ARTEFAK (otomatis) | F7: DIISI MAHASISWA | K7: DIISI DOSEN | N7: HASIL (otomatis)
A8: No | B8: Minggu | C8: Kode | D8: Artefak Notion | E8: Nama file PDF | F8: Level klaim (0–4) | G8: Link PDF di GDrive (wajib) | H8: PIC | I8: Catatan | J8: Link Notion (opsional) | K8: Link valid? | L8: Level terverifikasi (0–4) | M8: Komentar dosen | N8: Level dihitung | O8: Selisih klaim − verifikasi | P8: Flag
A9: 1 | B9: =Peta_Artefak!B5 -> 1 | C9: =Peta_Artefak!C5 -> M01 | D9: =Peta_Artefak!D5 -> Workspace Notion kelompok & topik proyek | E9: M01_Workspace.pdf | N9: =IF(K9="Tidak",0,IF(L9="",0,L9)) -> 0 | O9: =IF(AND(F9<>"",L9<>""),F9-L9,"") | P9: =IF(AND(F9<>"",F9>0,G9=""),"Link PDF kosong",IF(AND(O9<>"",N(O9)>=2),"Overclaim",IF(AND(F9<>"",L9=""),"Belum diverifikasi","")))
A10: 2 | B10: =Peta_Artefak!B6 -> 2 | C10: =Peta_Artefak!C6 -> M02 | D10: =Peta_Artefak!D6 -> Problem Statement & Business Case | E10: M02_BusinessCase.pdf | N10: =IF(K10="Tidak",0,IF(L10="",0,L10)) -> 0 | O10: =IF(AND(F10<>"",L10<>""),F10-L10,"") | P10: =IF(AND(F10<>"",F10>0,G10=""),"Link PDF kosong",IF(AND(O10<>"",N(O10)>=2),"Overclaim",IF(AND(F10<>"",L10=""),"Belum diverifikasi","")))
A11: 3 | B11: =Peta_Artefak!B7 -> 3 | C11: =Peta_Artefak!C7 -> M03 | D11: =Peta_Artefak!D7 -> Stakeholder Register & Engagement Plan | E11: M03_StakeholderRegister.pdf | N11: =IF(K11="Tidak",0,IF(L11="",0,L11)) -> 0 | O11: =IF(AND(F11<>"",L11<>""),F11-L11,"") | P11: =IF(AND(F11<>"",F11>0,G11=""),"Link PDF kosong",IF(AND(O11<>"",N(O11)>=2),"Overclaim",IF(AND(F11<>"",L11=""),"Belum diverifikasi","")))
A12: 4 | B12: =Peta_Artefak!B8 -> 5 | C12: =Peta_Artefak!C8 -> M05 | D12: =Peta_Artefak!D8 -> Project Charter | E12: M05_ProjectCharter.pdf | N12: =IF(K12="Tidak",0,IF(L12="",0,L12)) -> 0 | O12: =IF(AND(F12<>"",L12<>""),F12-L12,"") | P12: =IF(AND(F12<>"",F12>0,G12=""),"Link PDF kosong",IF(AND(O12<>"",N(O12)>=2),"Overclaim",IF(AND(F12<>"",L12=""),"Belum diverifikasi","")))
A13: 5 | B13: =Peta_Artefak!B9 -> 6 | C13: =Peta_Artefak!C9 -> M06a | D13: =Peta_Artefak!D9 -> Scope Statement | E13: M06a_ScopeStatement.pdf | N13: =IF(K13="Tidak",0,IF(L13="",0,L13)) -> 0 | O13: =IF(AND(F13<>"",L13<>""),F13-L13,"") | P13: =IF(AND(F13<>"",F13>0,G13=""),"Link PDF kosong",IF(AND(O13<>"",N(O13)>=2),"Overclaim",IF(AND(F13<>"",L13=""),"Belum diverifikasi","")))
A14: 6 | B14: =Peta_Artefak!B10 -> 6 | C14: =Peta_Artefak!C10 -> M06b | D14: =Peta_Artefak!D10 -> Work Breakdown Structure | E14: M06b_WBS.pdf | N14: =IF(K14="Tidak",0,IF(L14="",0,L14)) -> 0 | O14: =IF(AND(F14<>"",L14<>""),F14-L14,"") | P14: =IF(AND(F14<>"",F14>0,G14=""),"Link PDF kosong",IF(AND(O14<>"",N(O14)>=2),"Overclaim",IF(AND(F14<>"",L14=""),"Belum diverifikasi","")))
A15: 7 | B15: =Peta_Artefak!B11 -> 6 | C15: =Peta_Artefak!C11 -> M06c | D15: =Peta_Artefak!D11 -> Model Kebutuhan (Use Case) | E15: M06c_UseCase.pdf | N15: =IF(K15="Tidak",0,IF(L15="",0,L15)) -> 0 | O15: =IF(AND(F15<>"",L15<>""),F15-L15,"") | P15: =IF(AND(F15<>"",F15>0,G15=""),"Link PDF kosong",IF(AND(O15<>"",N(O15)>=2),"Overclaim",IF(AND(F15<>"",L15=""),"Belum diverifikasi","")))
A16: 8 | B16: =Peta_Artefak!B12 -> 7 | C16: =Peta_Artefak!C12 -> M07 | D16: =Peta_Artefak!D12 -> Jadwal Proyek (Timeline/Gantt) | E16: M07_JadwalProyek.pdf | N16: =IF(K16="Tidak",0,IF(L16="",0,L16)) -> 0 | O16: =IF(AND(F16<>"",L16<>""),F16-L16,"") | P16: =IF(AND(F16<>"",F16>0,G16=""),"Link PDF kosong",IF(AND(O16<>"",N(O16)>=2),"Overclaim",IF(AND(F16<>"",L16=""),"Belum diverifikasi","")))
A17: 9 | B17: =Peta_Artefak!B13 -> 8 | C17: =Peta_Artefak!C13 -> M08a | D17: =Peta_Artefak!D13 -> Laporan Tengah Semester (LTS) | E17: M08a_LaporanTengahSemester.pdf | N17: =IF(K17="Tidak",0,IF(L17="",0,L17)) -> 0 | O17: =IF(AND(F17<>"",L17<>""),F17-L17,"") | P17: =IF(AND(F17<>"",F17>0,G17=""),"Link PDF kosong",IF(AND(O17<>"",N(O17)>=2),"Overclaim",IF(AND(F17<>"",L17=""),"Belum diverifikasi","")))
A18: 10 | B18: =Peta_Artefak!B14 -> 8 | C18: =Peta_Artefak!C14 -> M08b | D18: =Peta_Artefak!D14 -> Slide Presentasi LTS | E18: M08b_PresentasiLTS.pdf | N18: =IF(K18="Tidak",0,IF(L18="",0,L18)) -> 0 | O18: =IF(AND(F18<>"",L18<>""),F18-L18,"") | P18: =IF(AND(F18<>"",F18>0,G18=""),"Link PDF kosong",IF(AND(O18<>"",N(O18)>=2),"Overclaim",IF(AND(F18<>"",L18=""),"Belum diverifikasi","")))
D20: RINGKASAN
D21: Target capaian Minggu 8 | F21: =SUMPRODUCT(Peta_Artefak!$H$5:$H$14,Peta_Artefak!$I$5:$I$14)/400 -> 0.8475
D22: Capaian menurut klaim kelompok | F22: =SUMPRODUCT(Peta_Artefak!$H$5:$H$14,F9:F18)/400 -> 0
D23: Capaian terverifikasi dosen | F23: =SUMPRODUCT(Peta_Artefak!$H$5:$H$14,N9:N18)/400 -> 0
D24: SPI (capaian ÷ target) | F24: =IF(F21=0,0,F23/F21) -> 0
D25: Status | F25: =IF(COUNT(L9:L18)=0,"Belum diverifikasi",IF(F24>=Panduan_Dosen!$C$25,"On Track",IF(F24>=Panduan_Dosen!$C$26,"Perlu Perhatian","Kritis"))) -> Belum diverifikasi
D26: Setara progres proyek keseluruhan | F26: =F23*Panduan_Dosen!$C$14 -> 0
D27: Jumlah artefak overclaim | F27: =COUNTIF(P9:P18,"Overclaim") -> 0
D28: Jumlah artefak belum diverifikasi | F28: =COUNTIF(P9:P18,"Belum diverifikasi") -> 0
D29: LTS: Ringkasan (B) (1–5)
D30: LTS: Hasil pelaksanaan (C.1–C.5) (1–5)
D31: LTS: Status & interpretasi capaian (C.6, C.7, E) (1–5)
D32: LTS: Keterlibatan stakeholder (D) (1–5)
D33: LTS: Kendala (F) (1–5)
D34: LTS: Rencana berikutnya (G) (1–5)
D35: LTS: Konsistensi & kerapian (1–5)
D36: SKOR LTS (0–100) | F36: =IF(COUNT(F29:F35)<7,"",ROUND(SUMPRODUCT(F29:F35,Panduan_Dosen!$C$31:$C$37)/SUM(Panduan_Dosen!$C$31:$C$37)/5*100,1))
D37: Presentasi: Struktur & pengelolaan waktu (1–5)
D38: Presentasi: Akurasi status (rencana vs realisasi) (1–5)
D39: Presentasi: Analisis kendala & rencana pemulihan (1–5)
D40: Presentasi: Penguasaan & partisipasi tim (1–5)
D41: SKOR PRESENTASI (0–100) | F41: =IF(COUNT(F37:F40)<4,"",ROUND(SUMPRODUCT(F37:F40,Panduan_Dosen!$C$42:$C$45)/SUM(Panduan_Dosen!$C$42:$C$45)/5*100,1))
D42: NILAI UTS (0–100) | F42: =IF(OR(COUNT(L9:L18)=0,F36="",F41=""),"",ROUND(Panduan_Dosen!$C$18*MIN(F24,1)*100+Panduan_Dosen!$C$19*F36+Panduan_Dosen!$C$20*F41,1))

Sheet Kel2
A1: Self-Assessment UTS – Artefak Proyek (Minggu 1–8)
A2: Kelompok | D2: Kel. 2 (Ailsa dkk.)
A3: Topik | D3: OutGear Station – penyewaan & inventaris alat outdoor
A4: Link folder GDrive Snapshot_UTS
A5: Petunjuk | D5: Isi kolom kuning saja. Cara pengisian ada di sheet Panduan_Mahasiswa.
A7: ARTEFAK (otomatis) | F7: DIISI MAHASISWA | K7: DIISI DOSEN | N7: HASIL (otomatis)
A8: No | B8: Minggu | C8: Kode | D8: Artefak Notion | E8: Nama file PDF | F8: Level klaim (0–4) | G8: Link PDF di GDrive (wajib) | H8: PIC | I8: Catatan | J8: Link Notion (opsional) | K8: Link valid? | L8: Level terverifikasi (0–4) | M8: Komentar dosen | N8: Level dihitung | O8: Selisih klaim − verifikasi | P8: Flag
A9: 1 | B9: =Peta_Artefak!B5 -> 1 | C9: =Peta_Artefak!C5 -> M01 | D9: =Peta_Artefak!D5 -> Workspace Notion kelompok & topik proyek | E9: M01_Workspace.pdf | N9: =IF(K9="Tidak",0,IF(L9="",0,L9)) -> 0 | O9: =IF(AND(F9<>"",L9<>""),F9-L9,"") | P9: =IF(AND(F9<>"",F9>0,G9=""),"Link PDF kosong",IF(AND(O9<>"",N(O9)>=2),"Overclaim",IF(AND(F9<>"",L9=""),"Belum diverifikasi","")))
A10: 2 | B10: =Peta_Artefak!B6 -> 2 | C10: =Peta_Artefak!C6 -> M02 | D10: =Peta_Artefak!D6 -> Problem Statement & Business Case | E10: M02_BusinessCase.pdf | N10: =IF(K10="Tidak",0,IF(L10="",0,L10)) -> 0 | O10: =IF(AND(F10<>"",L10<>""),F10-L10,"") | P10: =IF(AND(F10<>"",F10>0,G10=""),"Link PDF kosong",IF(AND(O10<>"",N(O10)>=2),"Overclaim",IF(AND(F10<>"",L10=""),"Belum diverifikasi","")))
A11: 3 | B11: =Peta_Artefak!B7 -> 3 | C11: =Peta_Artefak!C7 -> M03 | D11: =Peta_Artefak!D7 -> Stakeholder Register & Engagement Plan | E11: M03_StakeholderRegister.pdf | N11: =IF(K11="Tidak",0,IF(L11="",0,L11)) -> 0 | O11: =IF(AND(F11<>"",L11<>""),F11-L11,"") | P11: =IF(AND(F11<>"",F11>0,G11=""),"Link PDF kosong",IF(AND(O11<>"",N(O11)>=2),"Overclaim",IF(AND(F11<>"",L11=""),"Belum diverifikasi","")))
A12: 4 | B12: =Peta_Artefak!B8 -> 5 | C12: =Peta_Artefak!C8 -> M05 | D12: =Peta_Artefak!D8 -> Project Charter | E12: M05_ProjectCharter.pdf | N12: =IF(K12="Tidak",0,IF(L12="",0,L12)) -> 0 | O12: =IF(AND(F12<>"",L12<>""),F12-L12,"") | P12: =IF(AND(F12<>"",F12>0,G12=""),"Link PDF kosong",IF(AND(O12<>"",N(O12)>=2),"Overclaim",IF(AND(F12<>"",L12=""),"Belum diverifikasi","")))
A13: 5 | B13: =Peta_Artefak!B9 -> 6 | C13: =Peta_Artefak!C9 -> M06a | D13: =Peta_Artefak!D9 -> Scope Statement | E13: M06a_ScopeStatement.pdf | N13: =IF(K13="Tidak",0,IF(L13="",0,L13)) -> 0 | O13: =IF(AND(F13<>"",L13<>""),F13-L13,"") | P13: =IF(AND(F13<>"",F13>0,G13=""),"Link PDF kosong",IF(AND(O13<>"",N(O13)>=2),"Overclaim",IF(AND(F13<>"",L13=""),"Belum diverifikasi","")))
A14: 6 | B14: =Peta_Artefak!B10 -> 6 | C14: =Peta_Artefak!C10 -> M06b | D14: =Peta_Artefak!D10 -> Work Breakdown Structure | E14: M06b_WBS.pdf | N14: =IF(K14="Tidak",0,IF(L14="",0,L14)) -> 0 | O14: =IF(AND(F14<>"",L14<>""),F14-L14,"") | P14: =IF(AND(F14<>"",F14>0,G14=""),"Link PDF kosong",IF(AND(O14<>"",N(O14)>=2),"Overclaim",IF(AND(F14<>"",L14=""),"Belum diverifikasi","")))
A15: 7 | B15: =Peta_Artefak!B11 -> 6 | C15: =Peta_Artefak!C11 -> M06c | D15: =Peta_Artefak!D11 -> Model Kebutuhan (Use Case) | E15: M06c_UseCase.pdf | N15: =IF(K15="Tidak",0,IF(L15="",0,L15)) -> 0 | O15: =IF(AND(F15<>"",L15<>""),F15-L15,"") | P15: =IF(AND(F15<>"",F15>0,G15=""),"Link PDF kosong",IF(AND(O15<>"",N(O15)>=2),"Overclaim",IF(AND(F15<>"",L15=""),"Belum diverifikasi","")))
A16: 8 | B16: =Peta_Artefak!B12 -> 7 | C16: =Peta_Artefak!C12 -> M07 | D16: =Peta_Artefak!D12 -> Jadwal Proyek (Timeline/Gantt) | E16: M07_JadwalProyek.pdf | N16: =IF(K16="Tidak",0,IF(L16="",0,L16)) -> 0 | O16: =IF(AND(F16<>"",L16<>""),F16-L16,"") | P16: =IF(AND(F16<>"",F16>0,G16=""),"Link PDF kosong",IF(AND(O16<>"",N(O16)>=2),"Overclaim",IF(AND(F16<>"",L16=""),"Belum diverifikasi","")))
A17: 9 | B17: =Peta_Artefak!B13 -> 8 | C17: =Peta_Artefak!C13 -> M08a | D17: =Peta_Artefak!D13 -> Laporan Tengah Semester (LTS) | E17: M08a_LaporanTengahSemester.pdf | N17: =IF(K17="Tidak",0,IF(L17="",0,L17)) -> 0 | O17: =IF(AND(F17<>"",L17<>""),F17-L17,"") | P17: =IF(AND(F17<>"",F17>0,G17=""),"Link PDF kosong",IF(AND(O17<>"",N(O17)>=2),"Overclaim",IF(AND(F17<>"",L17=""),"Belum diverifikasi","")))
A18: 10 | B18: =Peta_Artefak!B14 -> 8 | C18: =Peta_Artefak!C14 -> M08b | D18: =Peta_Artefak!D14 -> Slide Presentasi LTS | E18: M08b_PresentasiLTS.pdf | N18: =IF(K18="Tidak",0,IF(L18="",0,L18)) -> 0 | O18: =IF(AND(F18<>"",L18<>""),F18-L18,"") | P18: =IF(AND(F18<>"",F18>0,G18=""),"Link PDF kosong",IF(AND(O18<>"",N(O18)>=2),"Overclaim",IF(AND(F18<>"",L18=""),"Belum diverifikasi","")))
D20: RINGKASAN
D21: Target capaian Minggu 8 | F21: =SUMPRODUCT(Peta_Artefak!$H$5:$H$14,Peta_Artefak!$I$5:$I$14)/400 -> 0.8475
D22: Capaian menurut klaim kelompok | F22: =SUMPRODUCT(Peta_Artefak!$H$5:$H$14,F9:F18)/400 -> 0
D23: Capaian terverifikasi dosen | F23: =SUMPRODUCT(Peta_Artefak!$H$5:$H$14,N9:N18)/400 -> 0
D24: SPI (capaian ÷ target) | F24: =IF(F21=0,0,F23/F21) -> 0
D25: Status | F25: =IF(COUNT(L9:L18)=0,"Belum diverifikasi",IF(F24>=Panduan_Dosen!$C$25,"On Track",IF(F24>=Panduan_Dosen!$C$26,"Perlu Perhatian","Kritis"))) -> Belum diverifikasi
D26: Setara progres proyek keseluruhan | F26: =F23*Panduan_Dosen!$C$14 -> 0
D27: Jumlah artefak overclaim | F27: =COUNTIF(P9:P18,"Overclaim") -> 0
D28: Jumlah artefak belum diverifikasi | F28: =COUNTIF(P9:P18,"Belum diverifikasi") -> 0
D29: LTS: Ringkasan (B) (1–5)
D30: LTS: Hasil pelaksanaan (C.1–C.5) (1–5)
D31: LTS: Status & interpretasi capaian (C.6, C.7, E) (1–5)
D32: LTS: Keterlibatan stakeholder (D) (1–5)
D33: LTS: Kendala (F) (1–5)
D34: LTS: Rencana berikutnya (G) (1–5)
D35: LTS: Konsistensi & kerapian (1–5)
D36: SKOR LTS (0–100) | F36: =IF(COUNT(F29:F35)<7,"",ROUND(SUMPRODUCT(F29:F35,Panduan_Dosen!$C$31:$C$37)/SUM(Panduan_Dosen!$C$31:$C$37)/5*100,1))
D37: Presentasi: Struktur & pengelolaan waktu (1–5)
D38: Presentasi: Akurasi status (rencana vs realisasi) (1–5)
D39: Presentasi: Analisis kendala & rencana pemulihan (1–5)
D40: Presentasi: Penguasaan & partisipasi tim (1–5)
D41: SKOR PRESENTASI (0–100) | F41: =IF(COUNT(F37:F40)<4,"",ROUND(SUMPRODUCT(F37:F40,Panduan_Dosen!$C$42:$C$45)/SUM(Panduan_Dosen!$C$42:$C$45)/5*100,1))
D42: NILAI UTS (0–100) | F42: =IF(OR(COUNT(L9:L18)=0,F36="",F41=""),"",ROUND(Panduan_Dosen!$C$18*MIN(F24,1)*100+Panduan_Dosen!$C$19*F36+Panduan_Dosen!$C$20*F41,1))

Sheet Kel3
A1: Self-Assessment UTS – Artefak Proyek (Minggu 1–8)
A2: Kelompok | D2: Kel. 3 (Tria dkk.)
A3: Topik | D3: Kopstud – POS & pasokan multi-cabang
A4: Link folder GDrive Snapshot_UTS
A5: Petunjuk | D5: Isi kolom kuning saja. Cara pengisian ada di sheet Panduan_Mahasiswa.
A7: ARTEFAK (otomatis) | F7: DIISI MAHASISWA | K7: DIISI DOSEN | N7: HASIL (otomatis)
A8: No | B8: Minggu | C8: Kode | D8: Artefak Notion | E8: Nama file PDF | F8: Level klaim (0–4) | G8: Link PDF di GDrive (wajib) | H8: PIC | I8: Catatan | J8: Link Notion (opsional) | K8: Link valid? | L8: Level terverifikasi (0–4) | M8: Komentar dosen | N8: Level dihitung | O8: Selisih klaim − verifikasi | P8: Flag
A9: 1 | B9: =Peta_Artefak!B5 -> 1 | C9: =Peta_Artefak!C5 -> M01 | D9: =Peta_Artefak!D5 -> Workspace Notion kelompok & topik proyek | E9: M01_Workspace.pdf | N9: =IF(K9="Tidak",0,IF(L9="",0,L9)) -> 0 | O9: =IF(AND(F9<>"",L9<>""),F9-L9,"") | P9: =IF(AND(F9<>"",F9>0,G9=""),"Link PDF kosong",IF(AND(O9<>"",N(O9)>=2),"Overclaim",IF(AND(F9<>"",L9=""),"Belum diverifikasi","")))
A10: 2 | B10: =Peta_Artefak!B6 -> 2 | C10: =Peta_Artefak!C6 -> M02 | D10: =Peta_Artefak!D6 -> Problem Statement & Business Case | E10: M02_BusinessCase.pdf | N10: =IF(K10="Tidak",0,IF(L10="",0,L10)) -> 0 | O10: =IF(AND(F10<>"",L10<>""),F10-L10,"") | P10: =IF(AND(F10<>"",F10>0,G10=""),"Link PDF kosong",IF(AND(O10<>"",N(O10)>=2),"Overclaim",IF(AND(F10<>"",L10=""),"Belum diverifikasi","")))
A11: 3 | B11: =Peta_Artefak!B7 -> 3 | C11: =Peta_Artefak!C7 -> M03 | D11: =Peta_Artefak!D7 -> Stakeholder Register & Engagement Plan | E11: M03_StakeholderRegister.pdf | N11: =IF(K11="Tidak",0,IF(L11="",0,L11)) -> 0 | O11: =IF(AND(F11<>"",L11<>""),F11-L11,"") | P11: =IF(AND(F11<>"",F11>0,G11=""),"Link PDF kosong",IF(AND(O11<>"",N(O11)>=2),"Overclaim",IF(AND(F11<>"",L11=""),"Belum diverifikasi","")))
A12: 4 | B12: =Peta_Artefak!B8 -> 5 | C12: =Peta_Artefak!C8 -> M05 | D12: =Peta_Artefak!D8 -> Project Charter | E12: M05_ProjectCharter.pdf | N12: =IF(K12="Tidak",0,IF(L12="",0,L12)) -> 0 | O12: =IF(AND(F12<>"",L12<>""),F12-L12,"") | P12: =IF(AND(F12<>"",F12>0,G12=""),"Link PDF kosong",IF(AND(O12<>"",N(O12)>=2),"Overclaim",IF(AND(F12<>"",L12=""),"Belum diverifikasi","")))
A13: 5 | B13: =Peta_Artefak!B9 -> 6 | C13: =Peta_Artefak!C9 -> M06a | D13: =Peta_Artefak!D9 -> Scope Statement | E13: M06a_ScopeStatement.pdf | N13: =IF(K13="Tidak",0,IF(L13="",0,L13)) -> 0 | O13: =IF(AND(F13<>"",L13<>""),F13-L13,"") | P13: =IF(AND(F13<>"",F13>0,G13=""),"Link PDF kosong",IF(AND(O13<>"",N(O13)>=2),"Overclaim",IF(AND(F13<>"",L13=""),"Belum diverifikasi","")))
A14: 6 | B14: =Peta_Artefak!B10 -> 6 | C14: =Peta_Artefak!C10 -> M06b | D14: =Peta_Artefak!D10 -> Work Breakdown Structure | E14: M06b_WBS.pdf | N14: =IF(K14="Tidak",0,IF(L14="",0,L14)) -> 0 | O14: =IF(AND(F14<>"",L14<>""),F14-L14,"") | P14: =IF(AND(F14<>"",F14>0,G14=""),"Link PDF kosong",IF(AND(O14<>"",N(O14)>=2),"Overclaim",IF(AND(F14<>"",L14=""),"Belum diverifikasi","")))
A15: 7 | B15: =Peta_Artefak!B11 -> 6 | C15: =Peta_Artefak!C11 -> M06c | D15: =Peta_Artefak!D11 -> Model Kebutuhan (Use Case) | E15: M06c_UseCase.pdf | N15: =IF(K15="Tidak",0,IF(L15="",0,L15)) -> 0 | O15: =IF(AND(F15<>"",L15<>""),F15-L15,"") | P15: =IF(AND(F15<>"",F15>0,G15=""),"Link PDF kosong",IF(AND(O15<>"",N(O15)>=2),"Overclaim",IF(AND(F15<>"",L15=""),"Belum diverifikasi","")))
A16: 8 | B16: =Peta_Artefak!B12 -> 7 | C16: =Peta_Artefak!C12 -> M07 | D16: =Peta_Artefak!D12 -> Jadwal Proyek (Timeline/Gantt) | E16: M07_JadwalProyek.pdf | N16: =IF(K16="Tidak",0,IF(L16="",0,L16)) -> 0 | O16: =IF(AND(F16<>"",L16<>""),F16-L16,"") | P16: =IF(AND(F16<>"",F16>0,G16=""),"Link PDF kosong",IF(AND(O16<>"",N(O16)>=2),"Overclaim",IF(AND(F16<>"",L16=""),"Belum diverifikasi","")))
A17: 9 | B17: =Peta_Artefak!B13 -> 8 | C17: =Peta_Artefak!C13 -> M08a | D17: =Peta_Artefak!D13 -> Laporan Tengah Semester (LTS) | E17: M08a_LaporanTengahSemester.pdf | N17: =IF(K17="Tidak",0,IF(L17="",0,L17)) -> 0 | O17: =IF(AND(F17<>"",L17<>""),F17-L17,"") | P17: =IF(AND(F17<>"",F17>0,G17=""),"Link PDF kosong",IF(AND(O17<>"",N(O17)>=2),"Overclaim",IF(AND(F17<>"",L17=""),"Belum diverifikasi","")))
A18: 10 | B18: =Peta_Artefak!B14 -> 8 | C18: =Peta_Artefak!C14 -> M08b | D18: =Peta_Artefak!D14 -> Slide Presentasi LTS | E18: M08b_PresentasiLTS.pdf | N18: =IF(K18="Tidak",0,IF(L18="",0,L18)) -> 0 | O18: =IF(AND(F18<>"",L18<>""),F18-L18,"") | P18: =IF(AND(F18<>"",F18>0,G18=""),"Link PDF kosong",IF(AND(O18<>"",N(O18)>=2),"Overclaim",IF(AND(F18<>"",L18=""),"Belum diverifikasi","")))
D20: RINGKASAN
D21: Target capaian Minggu 8 | F21: =SUMPRODUCT(Peta_Artefak!$H$5:$H$14,Peta_Artefak!$I$5:$I$14)/400 -> 0.8475
D22: Capaian menurut klaim kelompok | F22: =SUMPRODUCT(Peta_Artefak!$H$5:$H$14,F9:F18)/400 -> 0
D23: Capaian terverifikasi dosen | F23: =SUMPRODUCT(Peta_Artefak!$H$5:$H$14,N9:N18)/400 -> 0
D24: SPI (capaian ÷ target) | F24: =IF(F21=0,0,F23/F21) -> 0
D25: Status | F25: =IF(COUNT(L9:L18)=0,"Belum diverifikasi",IF(F24>=Panduan_Dosen!$C$25,"On Track",IF(F24>=Panduan_Dosen!$C$26,"Perlu Perhatian","Kritis"))) -> Belum diverifikasi
D26: Setara progres proyek keseluruhan | F26: =F23*Panduan_Dosen!$C$14 -> 0
D27: Jumlah artefak overclaim | F27: =COUNTIF(P9:P18,"Overclaim") -> 0
D28: Jumlah artefak belum diverifikasi | F28: =COUNTIF(P9:P18,"Belum diverifikasi") -> 0
D29: LTS: Ringkasan (B) (1–5)
D30: LTS: Hasil pelaksanaan (C.1–C.5) (1–5)
D31: LTS: Status & interpretasi capaian (C.6, C.7, E) (1–5)
D32: LTS: Keterlibatan stakeholder (D) (1–5)
D33: LTS: Kendala (F) (1–5)
D34: LTS: Rencana berikutnya (G) (1–5)
D35: LTS: Konsistensi & kerapian (1–5)
D36: SKOR LTS (0–100) | F36: =IF(COUNT(F29:F35)<7,"",ROUND(SUMPRODUCT(F29:F35,Panduan_Dosen!$C$31:$C$37)/SUM(Panduan_Dosen!$C$31:$C$37)/5*100,1))
D37: Presentasi: Struktur & pengelolaan waktu (1–5)
D38: Presentasi: Akurasi status (rencana vs realisasi) (1–5)
D39: Presentasi: Analisis kendala & rencana pemulihan (1–5)
D40: Presentasi: Penguasaan & partisipasi tim (1–5)
D41: SKOR PRESENTASI (0–100) | F41: =IF(COUNT(F37:F40)<4,"",ROUND(SUMPRODUCT(F37:F40,Panduan_Dosen!$C$42:$C$45)/SUM(Panduan_Dosen!$C$42:$C$45)/5*100,1))
D42: NILAI UTS (0–100) | F42: =IF(OR(COUNT(L9:L18)=0,F36="",F41=""),"",ROUND(Panduan_Dosen!$C$18*MIN(F24,1)*100+Panduan_Dosen!$C$19*F36+Panduan_Dosen!$C$20*F41,1))

Sheet Kel4
A1: Self-Assessment UTS – Artefak Proyek (Minggu 1–8)
A2: Kelompok | D2: Kel. 4 (Kartiko dkk.)
A3: Topik | D3: Laundry Cihuy – pesanan, stok & pelacakan cucian
A4: Link folder GDrive Snapshot_UTS
A5: Petunjuk | D5: Isi kolom kuning saja. Cara pengisian ada di sheet Panduan_Mahasiswa.
A7: ARTEFAK (otomatis) | F7: DIISI MAHASISWA | K7: DIISI DOSEN | N7: HASIL (otomatis)
A8: No | B8: Minggu | C8: Kode | D8: Artefak Notion | E8: Nama file PDF | F8: Level klaim (0–4) | G8: Link PDF di GDrive (wajib) | H8: PIC | I8: Catatan | J8: Link Notion (opsional) | K8: Link valid? | L8: Level terverifikasi (0–4) | M8: Komentar dosen | N8: Level dihitung | O8: Selisih klaim − verifikasi | P8: Flag
A9: 1 | B9: =Peta_Artefak!B5 -> 1 | C9: =Peta_Artefak!C5 -> M01 | D9: =Peta_Artefak!D5 -> Workspace Notion kelompok & topik proyek | E9: M01_Workspace.pdf | N9: =IF(K9="Tidak",0,IF(L9="",0,L9)) -> 0 | O9: =IF(AND(F9<>"",L9<>""),F9-L9,"") | P9: =IF(AND(F9<>"",F9>0,G9=""),"Link PDF kosong",IF(AND(O9<>"",N(O9)>=2),"Overclaim",IF(AND(F9<>"",L9=""),"Belum diverifikasi","")))
A10: 2 | B10: =Peta_Artefak!B6 -> 2 | C10: =Peta_Artefak!C6 -> M02 | D10: =Peta_Artefak!D6 -> Problem Statement & Business Case | E10: M02_BusinessCase.pdf | N10: =IF(K10="Tidak",0,IF(L10="",0,L10)) -> 0 | O10: =IF(AND(F10<>"",L10<>""),F10-L10,"") | P10: =IF(AND(F10<>"",F10>0,G10=""),"Link PDF kosong",IF(AND(O10<>"",N(O10)>=2),"Overclaim",IF(AND(F10<>"",L10=""),"Belum diverifikasi","")))
A11: 3 | B11: =Peta_Artefak!B7 -> 3 | C11: =Peta_Artefak!C7 -> M03 | D11: =Peta_Artefak!D7 -> Stakeholder Register & Engagement Plan | E11: M03_StakeholderRegister.pdf | N11: =IF(K11="Tidak",0,IF(L11="",0,L11)) -> 0 | O11: =IF(AND(F11<>"",L11<>""),F11-L11,"") | P11: =IF(AND(F11<>"",F11>0,G11=""),"Link PDF kosong",IF(AND(O11<>"",N(O11)>=2),"Overclaim",IF(AND(F11<>"",L11=""),"Belum diverifikasi","")))
A12: 4 | B12: =Peta_Artefak!B8 -> 5 | C12: =Peta_Artefak!C8 -> M05 | D12: =Peta_Artefak!D8 -> Project Charter | E12: M05_ProjectCharter.pdf | N12: =IF(K12="Tidak",0,IF(L12="",0,L12)) -> 0 | O12: =IF(AND(F12<>"",L12<>""),F12-L12,"") | P12: =IF(AND(F12<>"",F12>0,G12=""),"Link PDF kosong",IF(AND(O12<>"",N(O12)>=2),"Overclaim",IF(AND(F12<>"",L12=""),"Belum diverifikasi","")))
A13: 5 | B13: =Peta_Artefak!B9 -> 6 | C13: =Peta_Artefak!C9 -> M06a | D13: =Peta_Artefak!D9 -> Scope Statement | E13: M06a_ScopeStatement.pdf | N13: =IF(K13="Tidak",0,IF(L13="",0,L13)) -> 0 | O13: =IF(AND(F13<>"",L13<>""),F13-L13,"") | P13: =IF(AND(F13<>"",F13>0,G13=""),"Link PDF kosong",IF(AND(O13<>"",N(O13)>=2),"Overclaim",IF(AND(F13<>"",L13=""),"Belum diverifikasi","")))
A14: 6 | B14: =Peta_Artefak!B10 -> 6 | C14: =Peta_Artefak!C10 -> M06b | D14: =Peta_Artefak!D10 -> Work Breakdown Structure | E14: M06b_WBS.pdf | N14: =IF(K14="Tidak",0,IF(L14="",0,L14)) -> 0 | O14: =IF(AND(F14<>"",L14<>""),F14-L14,"") | P14: =IF(AND(F14<>"",F14>0,G14=""),"Link PDF kosong",IF(AND(O14<>"",N(O14)>=2),"Overclaim",IF(AND(F14<>"",L14=""),"Belum diverifikasi","")))
A15: 7 | B15: =Peta_Artefak!B11 -> 6 | C15: =Peta_Artefak!C11 -> M06c | D15: =Peta_Artefak!D11 -> Model Kebutuhan (Use Case) | E15: M06c_UseCase.pdf | N15: =IF(K15="Tidak",0,IF(L15="",0,L15)) -> 0 | O15: =IF(AND(F15<>"",L15<>""),F15-L15,"") | P15: =IF(AND(F15<>"",F15>0,G15=""),"Link PDF kosong",IF(AND(O15<>"",N(O15)>=2),"Overclaim",IF(AND(F15<>"",L15=""),"Belum diverifikasi","")))
A16: 8 | B16: =Peta_Artefak!B12 -> 7 | C16: =Peta_Artefak!C12 -> M07 | D16: =Peta_Artefak!D12 -> Jadwal Proyek (Timeline/Gantt) | E16: M07_JadwalProyek.pdf | N16: =IF(K16="Tidak",0,IF(L16="",0,L16)) -> 0 | O16: =IF(AND(F16<>"",L16<>""),F16-L16,"") | P16: =IF(AND(F16<>"",F16>0,G16=""),"Link PDF kosong",IF(AND(O16<>"",N(O16)>=2),"Overclaim",IF(AND(F16<>"",L16=""),"Belum diverifikasi","")))
A17: 9 | B17: =Peta_Artefak!B13 -> 8 | C17: =Peta_Artefak!C13 -> M08a | D17: =Peta_Artefak!D13 -> Laporan Tengah Semester (LTS) | E17: M08a_LaporanTengahSemester.pdf | N17: =IF(K17="Tidak",0,IF(L17="",0,L17)) -> 0 | O17: =IF(AND(F17<>"",L17<>""),F17-L17,"") | P17: =IF(AND(F17<>"",F17>0,G17=""),"Link PDF kosong",IF(AND(O17<>"",N(O17)>=2),"Overclaim",IF(AND(F17<>"",L17=""),"Belum diverifikasi","")))
A18: 10 | B18: =Peta_Artefak!B14 -> 8 | C18: =Peta_Artefak!C14 -> M08b | D18: =Peta_Artefak!D14 -> Slide Presentasi LTS | E18: M08b_PresentasiLTS.pdf | N18: =IF(K18="Tidak",0,IF(L18="",0,L18)) -> 0 | O18: =IF(AND(F18<>"",L18<>""),F18-L18,"") | P18: =IF(AND(F18<>"",F18>0,G18=""),"Link PDF kosong",IF(AND(O18<>"",N(O18)>=2),"Overclaim",IF(AND(F18<>"",L18=""),"Belum diverifikasi","")))
D20: RINGKASAN
D21: Target capaian Minggu 8 | F21: =SUMPRODUCT(Peta_Artefak!$H$5:$H$14,Peta_Artefak!$I$5:$I$14)/400 -> 0.8475
D22: Capaian menurut klaim kelompok | F22: =SUMPRODUCT(Peta_Artefak!$H$5:$H$14,F9:F18)/400 -> 0
D23: Capaian terverifikasi dosen | F23: =SUMPRODUCT(Peta_Artefak!$H$5:$H$14,N9:N18)/400 -> 0
D24: SPI (capaian ÷ target) | F24: =IF(F21=0,0,F23/F21) -> 0
D25: Status | F25: =IF(COUNT(L9:L18)=0,"Belum diverifikasi",IF(F24>=Panduan_Dosen!$C$25,"On Track",IF(F24>=Panduan_Dosen!$C$26,"Perlu Perhatian","Kritis"))) -> Belum diverifikasi
D26: Setara progres proyek keseluruhan | F26: =F23*Panduan_Dosen!$C$14 -> 0
D27: Jumlah artefak overclaim | F27: =COUNTIF(P9:P18,"Overclaim") -> 0
D28: Jumlah artefak belum diverifikasi | F28: =COUNTIF(P9:P18,"Belum diverifikasi") -> 0
D29: LTS: Ringkasan (B) (1–5)
D30: LTS: Hasil pelaksanaan (C.1–C.5) (1–5)
D31: LTS: Status & interpretasi capaian (C.6, C.7, E) (1–5)
D32: LTS: Keterlibatan stakeholder (D) (1–5)
D33: LTS: Kendala (F) (1–5)
D34: LTS: Rencana berikutnya (G) (1–5)
D35: LTS: Konsistensi & kerapian (1–5)
D36: SKOR LTS (0–100) | F36: =IF(COUNT(F29:F35)<7,"",ROUND(SUMPRODUCT(F29:F35,Panduan_Dosen!$C$31:$C$37)/SUM(Panduan_Dosen!$C$31:$C$37)/5*100,1))
D37: Presentasi: Struktur & pengelolaan waktu (1–5)
D38: Presentasi: Akurasi status (rencana vs realisasi) (1–5)
D39: Presentasi: Analisis kendala & rencana pemulihan (1–5)
D40: Presentasi: Penguasaan & partisipasi tim (1–5)
D41: SKOR PRESENTASI (0–100) | F41: =IF(COUNT(F37:F40)<4,"",ROUND(SUMPRODUCT(F37:F40,Panduan_Dosen!$C$42:$C$45)/SUM(Panduan_Dosen!$C$42:$C$45)/5*100,1))
D42: NILAI UTS (0–100) | F42: =IF(OR(COUNT(L9:L18)=0,F36="",F41=""),"",ROUND(Panduan_Dosen!$C$18*MIN(F24,1)*100+Panduan_Dosen!$C$19*F36+Panduan_Dosen!$C$20*F41,1))

Sheet Kel5
A1: Self-Assessment UTS – Artefak Proyek (Minggu 1–8)
A2: Kelompok | D2: Kel. 5 (Anindya dkk.)
A3: Topik | D3: PT Askara Mulia Sejahtera – stok & penjualan induk-varian
A4: Link folder GDrive Snapshot_UTS
A5: Petunjuk | D5: Isi kolom kuning saja. Cara pengisian ada di sheet Panduan_Mahasiswa.
A7: ARTEFAK (otomatis) | F7: DIISI MAHASISWA | K7: DIISI DOSEN | N7: HASIL (otomatis)
A8: No | B8: Minggu | C8: Kode | D8: Artefak Notion | E8: Nama file PDF | F8: Level klaim (0–4) | G8: Link PDF di GDrive (wajib) | H8: PIC | I8: Catatan | J8: Link Notion (opsional) | K8: Link valid? | L8: Level terverifikasi (0–4) | M8: Komentar dosen | N8: Level dihitung | O8: Selisih klaim − verifikasi | P8: Flag
A9: 1 | B9: =Peta_Artefak!B5 -> 1 | C9: =Peta_Artefak!C5 -> M01 | D9: =Peta_Artefak!D5 -> Workspace Notion kelompok & topik proyek | E9: M01_Workspace.pdf | N9: =IF(K9="Tidak",0,IF(L9="",0,L9)) -> 0 | O9: =IF(AND(F9<>"",L9<>""),F9-L9,"") | P9: =IF(AND(F9<>"",F9>0,G9=""),"Link PDF kosong",IF(AND(O9<>"",N(O9)>=2),"Overclaim",IF(AND(F9<>"",L9=""),"Belum diverifikasi","")))
A10: 2 | B10: =Peta_Artefak!B6 -> 2 | C10: =Peta_Artefak!C6 -> M02 | D10: =Peta_Artefak!D6 -> Problem Statement & Business Case | E10: M02_BusinessCase.pdf | N10: =IF(K10="Tidak",0,IF(L10="",0,L10)) -> 0 | O10: =IF(AND(F10<>"",L10<>""),F10-L10,"") | P10: =IF(AND(F10<>"",F10>0,G10=""),"Link PDF kosong",IF(AND(O10<>"",N(O10)>=2),"Overclaim",IF(AND(F10<>"",L10=""),"Belum diverifikasi","")))
A11: 3 | B11: =Peta_Artefak!B7 -> 3 | C11: =Peta_Artefak!C7 -> M03 | D11: =Peta_Artefak!D7 -> Stakeholder Register & Engagement Plan | E11: M03_StakeholderRegister.pdf | N11: =IF(K11="Tidak",0,IF(L11="",0,L11)) -> 0 | O11: =IF(AND(F11<>"",L11<>""),F11-L11,"") | P11: =IF(AND(F11<>"",F11>0,G11=""),"Link PDF kosong",IF(AND(O11<>"",N(O11)>=2),"Overclaim",IF(AND(F11<>"",L11=""),"Belum diverifikasi","")))
A12: 4 | B12: =Peta_Artefak!B8 -> 5 | C12: =Peta_Artefak!C8 -> M05 | D12: =Peta_Artefak!D8 -> Project Charter | E12: M05_ProjectCharter.pdf | N12: =IF(K12="Tidak",0,IF(L12="",0,L12)) -> 0 | O12: =IF(AND(F12<>"",L12<>""),F12-L12,"") | P12: =IF(AND(F12<>"",F12>0,G12=""),"Link PDF kosong",IF(AND(O12<>"",N(O12)>=2),"Overclaim",IF(AND(F12<>"",L12=""),"Belum diverifikasi","")))
A13: 5 | B13: =Peta_Artefak!B9 -> 6 | C13: =Peta_Artefak!C9 -> M06a | D13: =Peta_Artefak!D9 -> Scope Statement | E13: M06a_ScopeStatement.pdf | N13: =IF(K13="Tidak",0,IF(L13="",0,L13)) -> 0 | O13: =IF(AND(F13<>"",L13<>""),F13-L13,"") | P13: =IF(AND(F13<>"",F13>0,G13=""),"Link PDF kosong",IF(AND(O13<>"",N(O13)>=2),"Overclaim",IF(AND(F13<>"",L13=""),"Belum diverifikasi","")))
A14: 6 | B14: =Peta_Artefak!B10 -> 6 | C14: =Peta_Artefak!C10 -> M06b | D14: =Peta_Artefak!D10 -> Work Breakdown Structure | E14: M06b_WBS.pdf | N14: =IF(K14="Tidak",0,IF(L14="",0,L14)) -> 0 | O14: =IF(AND(F14<>"",L14<>""),F14-L14,"") | P14: =IF(AND(F14<>"",F14>0,G14=""),"Link PDF kosong",IF(AND(O14<>"",N(O14)>=2),"Overclaim",IF(AND(F14<>"",L14=""),"Belum diverifikasi","")))
A15: 7 | B15: =Peta_Artefak!B11 -> 6 | C15: =Peta_Artefak!C11 -> M06c | D15: =Peta_Artefak!D11 -> Model Kebutuhan (Use Case) | E15: M06c_UseCase.pdf | N15: =IF(K15="Tidak",0,IF(L15="",0,L15)) -> 0 | O15: =IF(AND(F15<>"",L15<>""),F15-L15,"") | P15: =IF(AND(F15<>"",F15>0,G15=""),"Link PDF kosong",IF(AND(O15<>"",N(O15)>=2),"Overclaim",IF(AND(F15<>"",L15=""),"Belum diverifikasi","")))
A16: 8 | B16: =Peta_Artefak!B12 -> 7 | C16: =Peta_Artefak!C12 -> M07 | D16: =Peta_Artefak!D12 -> Jadwal Proyek (Timeline/Gantt) | E16: M07_JadwalProyek.pdf | N16: =IF(K16="Tidak",0,IF(L16="",0,L16)) -> 0 | O16: =IF(AND(F16<>"",L16<>""),F16-L16,"") | P16: =IF(AND(F16<>"",F16>0,G16=""),"Link PDF kosong",IF(AND(O16<>"",N(O16)>=2),"Overclaim",IF(AND(F16<>"",L16=""),"Belum diverifikasi","")))
A17: 9 | B17: =Peta_Artefak!B13 -> 8 | C17: =Peta_Artefak!C13 -> M08a | D17: =Peta_Artefak!D13 -> Laporan Tengah Semester (LTS) | E17: M08a_LaporanTengahSemester.pdf | N17: =IF(K17="Tidak",0,IF(L17="",0,L17)) -> 0 | O17: =IF(AND(F17<>"",L17<>""),F17-L17,"") | P17: =IF(AND(F17<>"",F17>0,G17=""),"Link PDF kosong",IF(AND(O17<>"",N(O17)>=2),"Overclaim",IF(AND(F17<>"",L17=""),"Belum diverifikasi","")))
A18: 10 | B18: =Peta_Artefak!B14 -> 8 | C18: =Peta_Artefak!C14 -> M08b | D18: =Peta_Artefak!D14 -> Slide Presentasi LTS | E18: M08b_PresentasiLTS.pdf | N18: =IF(K18="Tidak",0,IF(L18="",0,L18)) -> 0 | O18: =IF(AND(F18<>"",L18<>""),F18-L18,"") | P18: =IF(AND(F18<>"",F18>0,G18=""),"Link PDF kosong",IF(AND(O18<>"",N(O18)>=2),"Overclaim",IF(AND(F18<>"",L18=""),"Belum diverifikasi","")))
D20: RINGKASAN
D21: Target capaian Minggu 8 | F21: =SUMPRODUCT(Peta_Artefak!$H$5:$H$14,Peta_Artefak!$I$5:$I$14)/400 -> 0.8475
D22: Capaian menurut klaim kelompok | F22: =SUMPRODUCT(Peta_Artefak!$H$5:$H$14,F9:F18)/400 -> 0
D23: Capaian terverifikasi dosen | F23: =SUMPRODUCT(Peta_Artefak!$H$5:$H$14,N9:N18)/400 -> 0
D24: SPI (capaian ÷ target) | F24: =IF(F21=0,0,F23/F21) -> 0
D25: Status | F25: =IF(COUNT(L9:L18)=0,"Belum diverifikasi",IF(F24>=Panduan_Dosen!$C$25,"On Track",IF(F24>=Panduan_Dosen!$C$26,"Perlu Perhatian","Kritis"))) -> Belum diverifikasi
D26: Setara progres proyek keseluruhan | F26: =F23*Panduan_Dosen!$C$14 -> 0
D27: Jumlah artefak overclaim | F27: =COUNTIF(P9:P18,"Overclaim") -> 0
D28: Jumlah artefak belum diverifikasi | F28: =COUNTIF(P9:P18,"Belum diverifikasi") -> 0
D29: LTS: Ringkasan (B) (1–5)
D30: LTS: Hasil pelaksanaan (C.1–C.5) (1–5)
D31: LTS: Status & interpretasi capaian (C.6, C.7, E) (1–5)
D32: LTS: Keterlibatan stakeholder (D) (1–5)
D33: LTS: Kendala (F) (1–5)
D34: LTS: Rencana berikutnya (G) (1–5)
D35: LTS: Konsistensi & kerapian (1–5)
D36: SKOR LTS (0–100) | F36: =IF(COUNT(F29:F35)<7,"",ROUND(SUMPRODUCT(F29:F35,Panduan_Dosen!$C$31:$C$37)/SUM(Panduan_Dosen!$C$31:$C$37)/5*100,1))
D37: Presentasi: Struktur & pengelolaan waktu (1–5)
D38: Presentasi: Akurasi status (rencana vs realisasi) (1–5)
D39: Presentasi: Analisis kendala & rencana pemulihan (1–5)
D40: Presentasi: Penguasaan & partisipasi tim (1–5)
D41: SKOR PRESENTASI (0–100) | F41: =IF(COUNT(F37:F40)<4,"",ROUND(SUMPRODUCT(F37:F40,Panduan_Dosen!$C$42:$C$45)/SUM(Panduan_Dosen!$C$42:$C$45)/5*100,1))
D42: NILAI UTS (0–100) | F42: =IF(OR(COUNT(L9:L18)=0,F36="",F41=""),"",ROUND(Panduan_Dosen!$C$18*MIN(F24,1)*100+Panduan_Dosen!$C$19*F36+Panduan_Dosen!$C$20*F41,1))

Sheet Rekap
A1: Rekap UTS – Monitoring & Evaluation SIB 3G
A2: Minggu 8 · artefak M1–M7 + Laporan Tengah Semester & Presentasi
A4: No | B4: Kelompok | C4: Topik | D4: Target M8 | E4: Capaian klaim | F4: Capaian terverifikasi | G4: SPI | H4: Status | I4: Setara progres proyek | J4: Overclaim | K4: Skor LTS | L4: Skor Presentasi | M4: Nilai UTS | N4: Catatan / rencana pemulihan
A5: 1 | B5: Kel. 1 (Nafisa dkk.) | C5: REBANT – pesanan, produksi MTS/MTO & persediaan | D5: =Kel1!F21 -> 0.8475 | E5: =Kel1!F22 -> 0 | F5: =Kel1!F23 -> 0 | G5: =Kel1!F24 -> 0 | H5: =Kel1!F25 -> Belum diverifikasi | I5: =Kel1!F26 -> 0 | J5: =Kel1!F27 -> 0 | K5: =Kel1!F36 | L5: =Kel1!F41 | M5: =Kel1!F42
A6: 2 | B6: Kel. 2 (Ailsa dkk.) | C6: OutGear Station – penyewaan & inventaris alat outdoor | D6: =Kel2!F21 -> 0.8475 | E6: =Kel2!F22 -> 0 | F6: =Kel2!F23 -> 0 | G6: =Kel2!F24 -> 0 | H6: =Kel2!F25 -> Belum diverifikasi | I6: =Kel2!F26 -> 0 | J6: =Kel2!F27 -> 0 | K6: =Kel2!F36 | L6: =Kel2!F41 | M6: =Kel2!F42
A7: 3 | B7: Kel. 3 (Tria dkk.) | C7: Kopstud – POS & pasokan multi-cabang | D7: =Kel3!F21 -> 0.8475 | E7: =Kel3!F22 -> 0 | F7: =Kel3!F23 -> 0 | G7: =Kel3!F24 -> 0 | H7: =Kel3!F25 -> Belum diverifikasi | I7: =Kel3!F26 -> 0 | J7: =Kel3!F27 -> 0 | K7: =Kel3!F36 | L7: =Kel3!F41 | M7: =Kel3!F42
A8: 4 | B8: Kel. 4 (Kartiko dkk.) | C8: Laundry Cihuy – pesanan, stok & pelacakan cucian | D8: =Kel4!F21 -> 0.8475 | E8: =Kel4!F22 -> 0 | F8: =Kel4!F23 -> 0 | G8: =Kel4!F24 -> 0 | H8: =Kel4!F25 -> Belum diverifikasi | I8: =Kel4!F26 -> 0 | J8: =Kel4!F27 -> 0 | K8: =Kel4!F36 | L8: =Kel4!F41 | M8: =Kel4!F42
A9: 5 | B9: Kel. 5 (Anindya dkk.) | C9: PT Askara Mulia Sejahtera – stok & penjualan induk-varian | D9: =Kel5!F21 -> 0.8475 | E9: =Kel5!F22 -> 0 | F9: =Kel5!F23 -> 0 | G9: =Kel5!F24 -> 0 | H9: =Kel5!F25 -> Belum diverifikasi | I9: =Kel5!F26 -> 0 | J9: =Kel5!F27 -> 0 | K9: =Kel5!F36 | L9: =Kel5!F41 | M9: =Kel5!F42
