Workbook

Sheet Petunjuk
A1: Petunjuk Penggunaan Rubrik
A3: Rubrik ini digunakan untuk menilai tim dan mahasiswa pada mata kuliah Pemrograman Web Lanjut (SIB Semester 5), mengikuti 4 checkpoint PBL: Proposal, Milestone 1, Milestone 2, dan Final.
A5: Ada dua sudut pandang penilaian pada setiap checkpoint:
A6: - Sudut pandang tim: rubrik tim dinilai satu kali per tim, mengukur kualitas hasil kerja tim (produk, dokumen, demo). Nilai ini menjadi dasar nilai seluruh anggota tim.
A7: - Sudut pandang individu: rubrik individu dinilai satu kali per mahasiswa, mengukur kontribusi teknis, kedisiplinan, kolaborasi, dan penguasaan materi masing-masing anggota.
A8: Nilai akhir mahasiswa menggabungkan kedua sudut pandang tersebut, bukan hanya nilai tim.
A10: 1. Buka sheet Rekap, isi nama tim pada bagian "Rekap Nilai Tim" dan data mahasiswa pada bagian "Rekap Nilai Mahasiswa" (pilih nama tim dari daftar dropdown).
A11: 2. Buka sheet Proposal, Milestone 1, Milestone 2, dan Final secara bergantian sesuai jadwal checkpoint.
A12: 3. Pada bagian "Penilaian Tim" di setiap sheet, isi skor 1 sampai 5 untuk setiap kriteria di baris tim yang sesuai. Kolom "Nilai (0-100)" terisi otomatis begitu seluruh kriteria pada baris tersebut terisi.
A13: 4. Pada bagian "Penilaian Individu" di setiap sheet, isi skor 1 sampai 5 untuk setiap mahasiswa. Kolom "Nilai Individu (0-100)" terisi otomatis begitu seluruh kriteria pada baris tersebut terisi.
A14: 5. Rubrik acuan (deskripsi setiap level skor 1-5) ada di bagian bawah setiap sheet checkpoint, sebagai referensi saat memberi skor. Lihat juga "Skala Penilaian Umum" di bawah untuk panduan umum sebelum membaca deskripsi rinci tiap kriteria.
A15: 6. Bobot tiap kriteria tim dapat disesuaikan pada tabel Rubrik Acuan Penilaian Tim; bobot kriteria individu dianggap setara sehingga tidak memiliki kolom bobot.
... A20: Gunakan skala umum berikut sebagai acuan awal saat menentukan skor. Skala ini melengkapi, bukan menggantikan, deskripsi rinci pada tabel Rubrik Acuan di bagian bawah setiap sheet checkpoint.
A21: Skor 1 - Sangat Kurang | B21: Tidak ada bukti kerja, atau hasil kerja tidak berfungsi/tidak sesuai sama sekali dengan yang diminta kriteria.
A22: Skor 2 - Kurang | B22: Ada bukti kerja namun sebagian besar aspek penting pada kriteria belum terpenuhi.
A23: Skor 3 - Cukup | B23: Sebagian besar aspek pada kriteria terpenuhi, namun masih ada kekurangan yang cukup berarti.
A24: Skor 4 - Baik | B24: Hampir seluruh aspek pada kriteria terpenuhi dengan baik, hanya kekurangan kecil yang mudah diperbaiki.
A25: Skor 5 - Sangat Baik | B25: Seluruh aspek pada kriteria terpenuhi dengan baik, sesuai atau melebihi standar yang diharapkan.
A27: Cara memberi skor secara objektif:
A28: - Bandingkan bukti kerja (dokumen, kode, hasil demo, atau laporan) dengan deskripsi tiap level pada tabel Rubrik Acuan, bukan dengan kesan umum terhadap tim atau mahasiswa.
A29: - Pilih level yang deskripsinya paling sesuai dengan bukti yang benar-benar teramati, bukan dengan potensi atau usaha yang direncanakan.
A30: - Jika bukti kerja berada di antara dua level, pilih level yang lebih rendah kecuali sebagian besar ciri level yang lebih tinggi sudah terpenuhi.
A31: - Gunakan patokan deskripsi yang sama untuk seluruh tim atau mahasiswa pada checkpoint yang sama, agar penilaian tetap konsisten walau diperiksa oleh dosen yang berbeda.
A33: Sel input (diisi manual)
A34: Sel hasil hitung otomatis (jangan diubah)

Sheet Proposal
A1: Rubrik Penilaian - Checkpoint Proposal (Minggu 4)
A2: Nilai tim dan nilai individu diisi di bawah ini; rubrik acuan skor 1-5 ada di bagian bawah sheet ini.
A4: Penilaian Tim (skor 1-5 per kriteria)
A5: Bobot (acuan) | B5: =B51 | C5: =B52 | D5: =B53 | E5: =B54 | F5: =B55
A6: Nama Tim | B6: Pembentukan Tim dan Pembagian Peran | C6: Eksplorasi dan Pemilihan Domain Bisnis | D6: Kejelasan Masalah dan Kebutuhan Pengguna | E6: Rancangan Model Data dan Daftar Fitur Awal (SCPMK0202-04001/04004) | F6: Kualitas Dokumen Proposal | G6: Rata Tertimbang (1-5) | H6: Nilai (0-100)
A7: =Rekap!$B$12 | G7: =IF(COUNT(B7:F7)<5,"",SUMPRODUCT(B7:F7,B$5:F$5)/SUM(B$5:F$5)) | H7: =IF(G7="","",G7/5*100)
A8: =Rekap!$B$13 | G8: =IF(COUNT(B8:F8)<5,"",SUMPRODUCT(B8:F8,B$5:F$5)/SUM(B$5:F$5)) | H8: =IF(G8="","",G8/5*100)
A9: =Rekap!$B$14 | G9: =IF(COUNT(B9:F9)<5,"",SUMPRODUCT(B9:F9,B$5:F$5)/SUM(B$5:F$5)) | H9: =IF(G9="","",G9/5*100)
A10: =Rekap!$B$15 | G10: =IF(COUNT(B10:F10)<5,"",SUMPRODUCT(B10:F10,B$5:F$5)/SUM(B$5:F$5)) | H10: =IF(G10="","",G10/5*100)
A11: =Rekap!$B$16 | G11: =IF(COUNT(B11:F11)<5,"",SUMPRODUCT(B11:F11,B$5:F$5)/SUM(B$5:F$5)) | H11: =IF(G11="","",G11/5*100)
A12: =Rekap!$B$17 | G12: =IF(COUNT(B12:F12)<5,"",SUMPRODUCT(B12:F12,B$5:F$5)/SUM(B$5:F$5)) | H12: =IF(G12="","",G12/5*100)
A13: Rata-rata Kelas | H13: =IFERROR(AVERAGE(H7:H12),"")
A15: Penilaian Individu (skor 1-5 per kriteria)
A16: No | B16: Nama Mahasiswa | C16: Tim | D16: Kontribusi Teknis | E16: Kedisiplinan dan Tanggung Jawab | F16: Kolaborasi dalam Tim | G16: Penguasaan Materi Produk | H16: Nilai Individu (0-100)
A17: 1 | B17: =IF(Rekap!$B$21="","",Rekap!$B$21) | C17: =IF(Rekap!$D$21="","",Rekap!$D$21) | H17: =IF(COUNT(D17:G17)<4,"",AVERAGE(D17:G17)/5*100)
A18: 2 | B18: =IF(Rekap!$B$22="","",Rekap!$B$22) | C18: =IF(Rekap!$D$22="","",Rekap!$D$22) | H18: =IF(COUNT(D18:G18)<4,"",AVERAGE(D18:G18)/5*100)
A19: 3 | B19: =IF(Rekap!$B$23="","",Rekap!$B$23) | C19: =IF(Rekap!$D$23="","",Rekap!$D$23) | H19: =IF(COUNT(D19:G19)<4,"",AVERAGE(D19:G19)/5*100)
A20: 4 | B20: =IF(Rekap!$B$24="","",Rekap!$B$24) | C20: =IF(Rekap!$D$24="","",Rekap!$D$24) | H20: =IF(COUNT(D20:G20)<4,"",AVERAGE(D20:G20)/5*100)
A21: 5 | B21: =IF(Rekap!$B$25="","",Rekap!$B$25) | C21: =IF(Rekap!$D$25="","",Rekap!$D$25) | H21: =IF(COUNT(D21:G21)<4,"",AVERAGE(D21:G21)/5*100)
A22: 6 | B22: =IF(Rekap!$B$26="","",Rekap!$B$26) | C22: =IF(Rekap!$D$26="","",Rekap!$D$26) | H22: =IF(COUNT(D22:G22)<4,"",AVERAGE(D22:G22)/5*100)
A23: 7 | B23: =IF(Rekap!$B$27="","",Rekap!$B$27) | C23: =IF(Rekap!$D$27="","",Rekap!$D$27) | H23: =IF(COUNT(D23:G23)<4,"",AVERAGE(D23:G23)/5*100)
A24: 8 | B24: =IF(Rekap!$B$28="","",Rekap!$B$28) | C24: =IF(Rekap!$D$28="","",Rekap!$D$28) | H24: =IF(COUNT(D24:G24)<4,"",AVERAGE(D24:G24)/5*100)
A25: 9 | B25: =IF(Rekap!$B$29="","",Rekap!$B$29) | C25: =IF(Rekap!$D$29="","",Rekap!$D$29) | H25: =IF(COUNT(D25:G25)<4,"",AVERAGE(D25:G25)/5*100)
A26: 10 | B26: =IF(Rekap!$B$30="","",Rekap!$B$30) | C26: =IF(Rekap!$D$30="","",Rekap!$D$30) | H26: =IF(COUNT(D26:G26)<4,"",AVERAGE(D26:G26)/5*100)
A27: 11 | B27: =IF(Rekap!$B$31="","",Rekap!$B$31) | C27: =IF(Rekap!$D$31="","",Rekap!$D$31) | H27: =IF(COUNT(D27:G27)<4,"",AVERAGE(D27:G27)/5*100)
A28: 12 | B28: =IF(Rekap!$B$32="","",Rekap!$B$32) | C28: =IF(Rekap!$D$32="","",Rekap!$D$32) | H28: =IF(COUNT(D28:G28)<4,"",AVERAGE(D28:G28)/5*100)
A29: 13 | B29: =IF(Rekap!$B$33="","",Rekap!$B$33) | C29: =IF(Rekap!$D$33="","",Rekap!$D$33) | H29: =IF(COUNT(D29:G29)<4,"",AVERAGE(D29:G29)/5*100)
A30: 14 | B30: =IF(Rekap!$B$34="","",Rekap!$B$34) | C30: =IF(Rekap!$D$34="","",Rekap!$D$34) | H30: =IF(COUNT(D30:G30)<4,"",AVERAGE(D30:G30)/5*100)
A31: 15 | B31: =IF(Rekap!$B$35="","",Rekap!$B$35) | C31: =IF(Rekap!$D$35="","",Rekap!$D$35) | H31: =IF(COUNT(D31:G31)<4,"",AVERAGE(D31:G31)/5*100)
A32: 16 | B32: =IF(Rekap!$B$36="","",Rekap!$B$36) | C32: =IF(Rekap!$D$36="","",Rekap!$D$36) | H32: =IF(COUNT(D32:G32)<4,"",AVERAGE(D32:G32)/5*100)
A33: 17 | B33: =IF(Rekap!$B$37="","",Rekap!$B$37) | C33: =IF(Rekap!$D$37="","",Rekap!$D$37) | H33: =IF(COUNT(D33:G33)<4,"",AVERAGE(D33:G33)/5*100)
A34: 18 | B34: =IF(Rekap!$B$38="","",Rekap!$B$38) | C34: =IF(Rekap!$D$38="","",Rekap!$D$38) | H34: =IF(COUNT(D34:G34)<4,"",AVERAGE(D34:G34)/5*100)
A35: 19 | B35: =IF(Rekap!$B$39="","",Rekap!$B$39) | C35: =IF(Rekap!$D$39="","",Rekap!$D$39) | H35: =IF(COUNT(D35:G35)<4,"",AVERAGE(D35:G35)/5*100)
A36: 20 | B36: =IF(Rekap!$B$40="","",Rekap!$B$40) | C36: =IF(Rekap!$D$40="","",Rekap!$D$40) | H36: =IF(COUNT(D36:G36)<4,"",AVERAGE(D36:G36)/5*100)
A37: 21 | B37: =IF(Rekap!$B$41="","",Rekap!$B$41) | C37: =IF(Rekap!$D$41="","",Rekap!$D$41) | H37: =IF(COUNT(D37:G37)<4,"",AVERAGE(D37:G37)/5*100)
A38: 22 | B38: =IF(Rekap!$B$42="","",Rekap!$B$42) | C38: =IF(Rekap!$D$42="","",Rekap!$D$42) | H38: =IF(COUNT(D38:G38)<4,"",AVERAGE(D38:G38)/5*100)
A39: 23 | B39: =IF(Rekap!$B$43="","",Rekap!$B$43) | C39: =IF(Rekap!$D$43="","",Rekap!$D$43) | H39: =IF(COUNT(D39:G39)<4,"",AVERAGE(D39:G39)/5*100)
A40: 24 | B40: =IF(Rekap!$B$44="","",Rekap!$B$44) | C40: =IF(Rekap!$D$44="","",Rekap!$D$44) | H40: =IF(COUNT(D40:G40)<4,"",AVERAGE(D40:G40)/5*100)
A41: 25 | B41: =IF(Rekap!$B$45="","",Rekap!$B$45) | C41: =IF(Rekap!$D$45="","",Rekap!$D$45) | H41: =IF(COUNT(D41:G41)<4,"",AVERAGE(D41:G41)/5*100)
A42: 26 | B42: =IF(Rekap!$B$46="","",Rekap!$B$46) | C42: =IF(Rekap!$D$46="","",Rekap!$D$46) | H42: =IF(COUNT(D42:G42)<4,"",AVERAGE(D42:G42)/5*100)
...

Sheet Milestone 1
A1: Rubrik Penilaian - Checkpoint Milestone 1 / UTS (Minggu 8)
A2: Nilai tim dan nilai individu diisi di bawah ini; rubrik acuan skor 1-5 ada di bagian bawah sheet ini.
A4: Penilaian Tim (skor 1-5 per kriteria)
A5: Bobot (acuan) | B5: =B51 | C5: =B52 | D5: =B53 | E5: =B54 | F5: =B55
A6: Nama Tim | B6: Progres Pengembangan Sesuai Rencana Proposal | C6: Kelengkapan CRUD dan Validasi Input (SCPMK0202-04002) | D6: Kualitas Arsitektur MVC dan Struktur Basis Data (SCPMK0202-04001) | E6: Autentikasi dan Otorisasi Peran (SCPMK0202-04003) | F6: Kesiapan Menjelaskan Keputusan Teknis | G6: Rata Tertimbang (1-5) | H6: Nilai (0-100)
A7: =Rekap!$B$12 | G7: =IF(COUNT(B7:F7)<5,"",SUMPRODUCT(B7:F7,B$5:F$5)/SUM(B$5:F$5)) | H7: =IF(G7="","",G7/5*100)
A8: =Rekap!$B$13 | G8: =IF(COUNT(B8:F8)<5,"",SUMPRODUCT(B8:F8,B$5:F$5)/SUM(B$5:F$5)) | H8: =IF(G8="","",G8/5*100)
A9: =Rekap!$B$14 | G9: =IF(COUNT(B9:F9)<5,"",SUMPRODUCT(B9:F9,B$5:F$5)/SUM(B$5:F$5)) | H9: =IF(G9="","",G9/5*100)
A10: =Rekap!$B$15 | G10: =IF(COUNT(B10:F10)<5,"",SUMPRODUCT(B10:F10,B$5:F$5)/SUM(B$5:F$5)) | H10: =IF(G10="","",G10/5*100)
A11: =Rekap!$B$16 | G11: =IF(COUNT(B11:F11)<5,"",SUMPRODUCT(B11:F11,B$5:F$5)/SUM(B$5:F$5)) | H11: =IF(G11="","",G11/5*100)
A12: =Rekap!$B$17 | G12: =IF(COUNT(B12:F12)<5,"",SUMPRODUCT(B12:F12,B$5:F$5)/SUM(B$5:F$5)) | H12: =IF(G12="","",G12/5*100)
A13: Rata-rata Kelas | H13: =IFERROR(AVERAGE(H7:H12),"")
A15: Penilaian Individu (skor 1-5 per kriteria)
A16: No | B16: Nama Mahasiswa | C16: Tim | D16: Kontribusi terhadap Pekerjaan Tim | E16: Kualitas Hasil Kerja yang Dikerjakan | F16: Pemahaman Teknis atas Bagian yang Dikerjakan | G16: Kesiapan Menjelaskan Bagian yang Dikerjakan | H16: Nilai Individu (0-100)
A17: 1 | B17: =IF(Rekap!$B$21="","",Rekap!$B$21) | C17: =IF(Rekap!$D$21="","",Rekap!$D$21) | H17: =IF(COUNT(D17:G17)<4,"",AVERAGE(D17:G17)/5*100)
A18: 2 | B18: =IF(Rekap!$B$22="","",Rekap!$B$22) | C18: =IF(Rekap!$D$22="","",Rekap!$D$22) | H18: =IF(COUNT(D18:G18)<4,"",AVERAGE(D18:G18)/5*100)
A19: 3 | B19: =IF(Rekap!$B$23="","",Rekap!$B$23) | C19: =IF(Rekap!$D$23="","",Rekap!$D$23) | H19: =IF(COUNT(D19:G19)<4,"",AVERAGE(D19:G19)/5*100)
A20: 4 | B20: =IF(Rekap!$B$24="","",Rekap!$B$24) | C20: =IF(Rekap!$D$24="","",Rekap!$D$24) | H20: =IF(COUNT(D20:G20)<4,"",AVERAGE(D20:G20)/5*100)
A21: 5 | B21: =IF(Rekap!$B$25="","",Rekap!$B$25) | C21: =IF(Rekap!$D$25="","",Rekap!$D$25) | H21: =IF(COUNT(D21:G21)<4,"",AVERAGE(D21:G21)/5*100)
A22: 6 | B22: =IF(Rekap!$B$26="","",Rekap!$B$26) | C22: =IF(Rekap!$D$26="","",Rekap!$D$26) | H22: =IF(COUNT(D22:G22)<4,"",AVERAGE(D22:G22)/5*100)
A23: 7 | B23: =IF(Rekap!$B$27="","",Rekap!$B$27) | C23: =IF(Rekap!$D$27="","",Rekap!$D$27) | H23: =IF(COUNT(D23:G23)<4,"",AVERAGE(D23:G23)/5*100)
A24: 8 | B24: =IF(Rekap!$B$28="","",Rekap!$B$28) | C24: =IF(Rekap!$D$28="","",Rekap!$D$28) | H24: =IF(COUNT(D24:G24)<4,"",AVERAGE(D24:G24)/5*100)
A25: 9 | B25: =IF(Rekap!$B$29="","",Rekap!$B$29) | C25: =IF(Rekap!$D$29="","",Rekap!$D$29) | H25: =IF(COUNT(D25:G25)<4,"",AVERAGE(D25:G25)/5*100)
A26: 10 | B26: =IF(Rekap!$B$30="","",Rekap!$B$30) | C26: =IF(Rekap!$D$30="","",Rekap!$D$30) | H26: =IF(COUNT(D26:G26)<4,"",AVERAGE(D26:G26)/5*100)
A27: 11 | B27: =IF(Rekap!$B$31="","",Rekap!$B$31) | C27: =IF(Rekap!$D$31="","",Rekap!$D$31) | H27: =IF(COUNT(D27:G27)<4,"",AVERAGE(D27:G27)/5*100)
A28: 12 | B28: =IF(Rekap!$B$32="","",Rekap!$B$32) | C28: =IF(Rekap!$D$32="","",Rekap!$D$32) | H28: =IF(COUNT(D28:G28)<4,"",AVERAGE(D28:G28)/5*100)
A29: 13 | B29: =IF(Rekap!$B$33="","",Rekap!$B$33) | C29: =IF(Rekap!$D$33="","",Rekap!$D$33) | H29: =IF(COUNT(D29:G29)<4,"",AVERAGE(D29:G29)/5*100)
A30: 14 | B30: =IF(Rekap!$B$34="","",Rekap!$B$34) | C30: =IF(Rekap!$D$34="","",Rekap!$D$34) | H30: =IF(COUNT(D30:G30)<4,"",AVERAGE(D30:G30)/5*100)
A31: 15 | B31: =IF(Rekap!$B$35="","",Rekap!$B$35) | C31: =IF(Rekap!$D$35="","",Rekap!$D$35) | H31: =IF(COUNT(D31:G31)<4,"",AVERAGE(D31:G31)/5*100)
A32: 16 | B32: =IF(Rekap!$B$36="","",Rekap!$B$36) | C32: =IF(Rekap!$D$36="","",Rekap!$D$36) | H32: =IF(COUNT(D32:G32)<4,"",AVERAGE(D32:G32)/5*100)
A33: 17 | B33: =IF(Rekap!$B$37="","",Rekap!$B$37) | C33: =IF(Rekap!$D$37="","",Rekap!$D$37) | H33: =IF(COUNT(D33:G33)<4,"",AVERAGE(D33:G33)/5*100)
A34: 18 | B34: =IF(Rekap!$B$38="","",Rekap!$B$38) | C34: =IF(Rekap!$D$38="","",Rekap!$D$38) | H34: =IF(COUNT(D34:G34)<4,"",AVERAGE(D34:G34)/5*100)
A35: 19 | B35: =IF(Rekap!$B$39="","",Rekap!$B$39) | C35: =IF(Rekap!$D$39="","",Rekap!$D$39) | H35: =IF(COUNT(D35:G35)<4,"",AVERAGE(D35:G35)/5*100)
A36: 20 | B36: =IF(Rekap!$B$40="","",Rekap!$B$40) | C36: =IF(Rekap!$D$40="","",Rekap!$D$40) | H36: =IF(COUNT(D36:G36)<4,"",AVERAGE(D36:G36)/5*100)
A37: 21 | B37: =IF(Rekap!$B$41="","",Rekap!$B$41) | C37: =IF(Rekap!$D$41="","",Rekap!$D$41) | H37: =IF(COUNT(D37:G37)<4,"",AVERAGE(D37:G37)/5*100)
A38: 22 | B38: =IF(Rekap!$B$42="","",Rekap!$B$42) | C38: =IF(Rekap!$D$42="","",Rekap!$D$42) | H38: =IF(COUNT(D38:G38)<4,"",AVERAGE(D38:G38)/5*100)
A39: 23 | B39: =IF(Rekap!$B$43="","",Rekap!$B$43) | C39: =IF(Rekap!$D$43="","",Rekap!$D$43) | H39: =IF(COUNT(D39:G39)<4,"",AVERAGE(D39:G39)/5*100)
A40: 24 | B40: =IF(Rekap!$B$44="","",Rekap!$B$44) | C40: =IF(Rekap!$D$44="","",Rekap!$D$44) | H40: =IF(COUNT(D40:G40)<4,"",AVERAGE(D40:G40)/5*100)
A41: 25 | B41: =IF(Rekap!$B$45="","",Rekap!$B$45) | C41: =IF(Rekap!$D$45="","",Rekap!$D$45) | H41: =IF(COUNT(D41:G41)<4,"",AVERAGE(D41:G41)/5*100)
A42: 26 | B42: =IF(Rekap!$B$46="","",Rekap!$B$46) | C42: =IF(Rekap!$D$46="","",Rekap!$D$46) | H42: =IF(COUNT(D42:G42)<4,"",AVERAGE(D42:G42)/5*100)
...

Sheet Milestone 2
A1: Rubrik Penilaian - Checkpoint Milestone 2 (Minggu 12)
A2: Nilai tim dan nilai individu diisi di bawah ini; rubrik acuan skor 1-5 ada di bagian bawah sheet ini.
A4: Penilaian Tim (skor 1-5 per kriteria)
A5: Bobot (acuan) | B5: =B51 | C5: =B52 | D5: =B53 | E5: =B54 | F5: =B55
A6: Nama Tim | B6: Progres Pengembangan Sesuai Rencana | C6: Pengolahan Data dan Import/Export (SCPMK0202-04004) | D6: Desain dan Implementasi API (SCPMK0202-04003) | E6: Konsumsi API dari Sisi Klien | F6: Integrasi Fitur dan Perencanaan Teknis Lanjutan | G6: Rata Tertimbang (1-5) | H6: Nilai (0-100)
A7: =Rekap!$B$12 | G7: =IF(COUNT(B7:F7)<5,"",SUMPRODUCT(B7:F7,B$5:F$5)/SUM(B$5:F$5)) | H7: =IF(G7="","",G7/5*100)
A8: =Rekap!$B$13 | G8: =IF(COUNT(B8:F8)<5,"",SUMPRODUCT(B8:F8,B$5:F$5)/SUM(B$5:F$5)) | H8: =IF(G8="","",G8/5*100)
A9: =Rekap!$B$14 | G9: =IF(COUNT(B9:F9)<5,"",SUMPRODUCT(B9:F9,B$5:F$5)/SUM(B$5:F$5)) | H9: =IF(G9="","",G9/5*100)
A10: =Rekap!$B$15 | G10: =IF(COUNT(B10:F10)<5,"",SUMPRODUCT(B10:F10,B$5:F$5)/SUM(B$5:F$5)) | H10: =IF(G10="","",G10/5*100)
A11: =Rekap!$B$16 | G11: =IF(COUNT(B11:F11)<5,"",SUMPRODUCT(B11:F11,B$5:F$5)/SUM(B$5:F$5)) | H11: =IF(G11="","",G11/5*100)
A12: =Rekap!$B$17 | G12: =IF(COUNT(B12:F12)<5,"",SUMPRODUCT(B12:F12,B$5:F$5)/SUM(B$5:F$5)) | H12: =IF(G12="","",G12/5*100)
A13: Rata-rata Kelas | H13: =IFERROR(AVERAGE(H7:H12),"")
A15: Penilaian Individu (skor 1-5 per kriteria)
A16: No | B16: Nama Mahasiswa | C16: Tim | D16: Kontribusi terhadap Pekerjaan Tim | E16: Kualitas Hasil Kerja yang Dikerjakan | F16: Pemahaman Teknis atas Bagian yang Dikerjakan | G16: Kesiapan Menjelaskan Bagian yang Dikerjakan | H16: Nilai Individu (0-100)
A17: 1 | B17: =IF(Rekap!$B$21="","",Rekap!$B$21) | C17: =IF(Rekap!$D$21="","",Rekap!$D$21) | H17: =IF(COUNT(D17:G17)<4,"",AVERAGE(D17:G17)/5*100)
A18: 2 | B18: =IF(Rekap!$B$22="","",Rekap!$B$22) | C18: =IF(Rekap!$D$22="","",Rekap!$D$22) | H18: =IF(COUNT(D18:G18)<4,"",AVERAGE(D18:G18)/5*100)
A19: 3 | B19: =IF(Rekap!$B$23="","",Rekap!$B$23) | C19: =IF(Rekap!$D$23="","",Rekap!$D$23) | H19: =IF(COUNT(D19:G19)<4,"",AVERAGE(D19:G19)/5*100)
A20: 4 | B20: =IF(Rekap!$B$24="","",Rekap!$B$24) | C20: =IF(Rekap!$D$24="","",Rekap!$D$24) | H20: =IF(COUNT(D20:G20)<4,"",AVERAGE(D20:G20)/5*100)
A21: 5 | B21: =IF(Rekap!$B$25="","",Rekap!$B$25) | C21: =IF(Rekap!$D$25="","",Rekap!$D$25) | H21: =IF(COUNT(D21:G21)<4,"",AVERAGE(D21:G21)/5*100)
A22: 6 | B22: =IF(Rekap!$B$26="","",Rekap!$B$26) | C22: =IF(Rekap!$D$26="","",Rekap!$D$26) | H22: =IF(COUNT(D22:G22)<4,"",AVERAGE(D22:G22)/5*100)
A23: 7 | B23: =IF(Rekap!$B$27="","",Rekap!$B$27) | C23: =IF(Rekap!$D$27="","",Rekap!$D$27) | H23: =IF(COUNT(D23:G23)<4,"",AVERAGE(D23:G23)/5*100)
A24: 8 | B24: =IF(Rekap!$B$28="","",Rekap!$B$28) | C24: =IF(Rekap!$D$28="","",Rekap!$D$28) | H24: =IF(COUNT(D24:G24)<4,"",AVERAGE(D24:G24)/5*100)
A25: 9 | B25: =IF(Rekap!$B$29="","",Rekap!$B$29) | C25: =IF(Rekap!$D$29="","",Rekap!$D$29) | H25: =IF(COUNT(D25:G25)<4,"",AVERAGE(D25:G25)/5*100)
A26: 10 | B26: =IF(Rekap!$B$30="","",Rekap!$B$30) | C26: =IF(Rekap!$D$30="","",Rekap!$D$30) | H26: =IF(COUNT(D26:G26)<4,"",AVERAGE(D26:G26)/5*100)
A27: 11 | B27: =IF(Rekap!$B$31="","",Rekap!$B$31) | C27: =IF(Rekap!$D$31="","",Rekap!$D$31) | H27: =IF(COUNT(D27:G27)<4,"",AVERAGE(D27:G27)/5*100)
A28: 12 | B28: =IF(Rekap!$B$32="","",Rekap!$B$32) | C28: =IF(Rekap!$D$32="","",Rekap!$D$32) | H28: =IF(COUNT(D28:G28)<4,"",AVERAGE(D28:G28)/5*100)
A29: 13 | B29: =IF(Rekap!$B$33="","",Rekap!$B$33) | C29: =IF(Rekap!$D$33="","",Rekap!$D$33) | H29: =IF(COUNT(D29:G29)<4,"",AVERAGE(D29:G29)/5*100)
A30: 14 | B30: =IF(Rekap!$B$34="","",Rekap!$B$34) | C30: =IF(Rekap!$D$34="","",Rekap!$D$34) | H30: =IF(COUNT(D30:G30)<4,"",AVERAGE(D30:G30)/5*100)
A31: 15 | B31: =IF(Rekap!$B$35="","",Rekap!$B$35) | C31: =IF(Rekap!$D$35="","",Rekap!$D$35) | H31: =IF(COUNT(D31:G31)<4,"",AVERAGE(D31:G31)/5*100)
A32: 16 | B32: =IF(Rekap!$B$36="","",Rekap!$B$36) | C32: =IF(Rekap!$D$36="","",Rekap!$D$36) | H32: =IF(COUNT(D32:G32)<4,"",AVERAGE(D32:G32)/5*100)
A33: 17 | B33: =IF(Rekap!$B$37="","",Rekap!$B$37) | C33: =IF(Rekap!$D$37="","",Rekap!$D$37) | H33: =IF(COUNT(D33:G33)<4,"",AVERAGE(D33:G33)/5*100)
A34: 18 | B34: =IF(Rekap!$B$38="","",Rekap!$B$38) | C34: =IF(Rekap!$D$38="","",Rekap!$D$38) | H34: =IF(COUNT(D34:G34)<4,"",AVERAGE(D34:G34)/5*100)
A35: 19 | B35: =IF(Rekap!$B$39="","",Rekap!$B$39) | C35: =IF(Rekap!$D$39="","",Rekap!$D$39) | H35: =IF(COUNT(D35:G35)<4,"",AVERAGE(D35:G35)/5*100)
A36: 20 | B36: =IF(Rekap!$B$40="","",Rekap!$B$40) | C36: =IF(Rekap!$D$40="","",Rekap!$D$40) | H36: =IF(COUNT(D36:G36)<4,"",AVERAGE(D36:G36)/5*100)
A37: 21 | B37: =IF(Rekap!$B$41="","",Rekap!$B$41) | C37: =IF(Rekap!$D$41="","",Rekap!$D$41) | H37: =IF(COUNT(D37:G37)<4,"",AVERAGE(D37:G37)/5*100)
A38: 22 | B38: =IF(Rekap!$B$42="","",Rekap!$B$42) | C38: =IF(Rekap!$D$42="","",Rekap!$D$42) | H38: =IF(COUNT(D38:G38)<4,"",AVERAGE(D38:G38)/5*100)
A39: 23 | B39: =IF(Rekap!$B$43="","",Rekap!$B$43) | C39: =IF(Rekap!$D$43="","",Rekap!$D$43) | H39: =IF(COUNT(D39:G39)<4,"",AVERAGE(D39:G39)/5*100)
A40: 24 | B40: =IF(Rekap!$B$44="","",Rekap!$B$44) | C40: =IF(Rekap!$D$44="","",Rekap!$D$44) | H40: =IF(COUNT(D40:G40)<4,"",AVERAGE(D40:G40)/5*100)
A41: 25 | B41: =IF(Rekap!$B$45="","",Rekap!$B$45) | C41: =IF(Rekap!$D$45="","",Rekap!$D$45) | H41: =IF(COUNT(D41:G41)<4,"",AVERAGE(D41:G41)/5*100)
A42: 26 | B42: =IF(Rekap!$B$46="","",Rekap!$B$46) | C42: =IF(Rekap!$D$46="","",Rekap!$D$46) | H42: =IF(COUNT(D42:G42)<4,"",AVERAGE(D42:G42)/5*100)
...

Sheet Final
A1: Rubrik Penilaian - Checkpoint Final / UAS (Minggu 16-17)
A2: Nilai tim dan nilai individu diisi di bawah ini; rubrik acuan skor 1-5 ada di bagian bawah sheet ini.
A4: Penilaian Tim (skor 1-5 per kriteria)
A5: Bobot (acuan) | B5: =B51 | C5: =B52 | D5: =B53 | E5: =B54 | F5: =B55
A6: Nama Tim | B6: Progres Finalisasi dan Kesiapan Deployment | C6: Kelengkapan Fitur Akhir Sesuai Kebutuhan Pengguna | D6: Kualitas Teknis dan Maintainability Kode | E6: Pengujian dan Penanganan Bug | F6: Kesiapan Menjelaskan Keputusan Teknis | G6: Rata Tertimbang (1-5) | H6: Nilai (0-100)
A7: =Rekap!$B$12 | G7: =IF(COUNT(B7:F7)<5,"",SUMPRODUCT(B7:F7,B$5:F$5)/SUM(B$5:F$5)) | H7: =IF(G7="","",G7/5*100)
A8: =Rekap!$B$13 | G8: =IF(COUNT(B8:F8)<5,"",SUMPRODUCT(B8:F8,B$5:F$5)/SUM(B$5:F$5)) | H8: =IF(G8="","",G8/5*100)
A9: =Rekap!$B$14 | G9: =IF(COUNT(B9:F9)<5,"",SUMPRODUCT(B9:F9,B$5:F$5)/SUM(B$5:F$5)) | H9: =IF(G9="","",G9/5*100)
A10: =Rekap!$B$15 | G10: =IF(COUNT(B10:F10)<5,"",SUMPRODUCT(B10:F10,B$5:F$5)/SUM(B$5:F$5)) | H10: =IF(G10="","",G10/5*100)
A11: =Rekap!$B$16 | G11: =IF(COUNT(B11:F11)<5,"",SUMPRODUCT(B11:F11,B$5:F$5)/SUM(B$5:F$5)) | H11: =IF(G11="","",G11/5*100)
A12: =Rekap!$B$17 | G12: =IF(COUNT(B12:F12)<5,"",SUMPRODUCT(B12:F12,B$5:F$5)/SUM(B$5:F$5)) | H12: =IF(G12="","",G12/5*100)
A13: Rata-rata Kelas | H13: =IFERROR(AVERAGE(H7:H12),"")
A15: Penilaian Individu (skor 1-5 per kriteria)
A16: No | B16: Nama Mahasiswa | C16: Tim | D16: Kontribusi terhadap Pekerjaan Tim | E16: Kualitas Hasil Kerja yang Dikerjakan | F16: Pemahaman Teknis atas Bagian yang Dikerjakan | G16: Kesiapan Menjelaskan Bagian yang Dikerjakan | H16: Nilai Individu (0-100)
A17: 1 | B17: =IF(Rekap!$B$21="","",Rekap!$B$21) | C17: =IF(Rekap!$D$21="","",Rekap!$D$21) | H17: =IF(COUNT(D17:G17)<4,"",AVERAGE(D17:G17)/5*100)
A18: 2 | B18: =IF(Rekap!$B$22="","",Rekap!$B$22) | C18: =IF(Rekap!$D$22="","",Rekap!$D$22) | H18: =IF(COUNT(D18:G18)<4,"",AVERAGE(D18:G18)/5*100)
A19: 3 | B19: =IF(Rekap!$B$23="","",Rekap!$B$23) | C19: =IF(Rekap!$D$23="","",Rekap!$D$23) | H19: =IF(COUNT(D19:G19)<4,"",AVERAGE(D19:G19)/5*100)
A20: 4 | B20: =IF(Rekap!$B$24="","",Rekap!$B$24) | C20: =IF(Rekap!$D$24="","",Rekap!$D$24) | H20: =IF(COUNT(D20:G20)<4,"",AVERAGE(D20:G20)/5*100)
A21: 5 | B21: =IF(Rekap!$B$25="","",Rekap!$B$25) | C21: =IF(Rekap!$D$25="","",Rekap!$D$25) | H21: =IF(COUNT(D21:G21)<4,"",AVERAGE(D21:G21)/5*100)
A22: 6 | B22: =IF(Rekap!$B$26="","",Rekap!$B$26) | C22: =IF(Rekap!$D$26="","",Rekap!$D$26) | H22: =IF(COUNT(D22:G22)<4,"",AVERAGE(D22:G22)/5*100)
A23: 7 | B23: =IF(Rekap!$B$27="","",Rekap!$B$27) | C23: =IF(Rekap!$D$27="","",Rekap!$D$27) | H23: =IF(COUNT(D23:G23)<4,"",AVERAGE(D23:G23)/5*100)
A24: 8 | B24: =IF(Rekap!$B$28="","",Rekap!$B$28) | C24: =IF(Rekap!$D$28="","",Rekap!$D$28) | H24: =IF(COUNT(D24:G24)<4,"",AVERAGE(D24:G24)/5*100)
A25: 9 | B25: =IF(Rekap!$B$29="","",Rekap!$B$29) | C25: =IF(Rekap!$D$29="","",Rekap!$D$29) | H25: =IF(COUNT(D25:G25)<4,"",AVERAGE(D25:G25)/5*100)
A26: 10 | B26: =IF(Rekap!$B$30="","",Rekap!$B$30) | C26: =IF(Rekap!$D$30="","",Rekap!$D$30) | H26: =IF(COUNT(D26:G26)<4,"",AVERAGE(D26:G26)/5*100)
A27: 11 | B27: =IF(Rekap!$B$31="","",Rekap!$B$31) | C27: =IF(Rekap!$D$31="","",Rekap!$D$31) | H27: =IF(COUNT(D27:G27)<4,"",AVERAGE(D27:G27)/5*100)
A28: 12 | B28: =IF(Rekap!$B$32="","",Rekap!$B$32) | C28: =IF(Rekap!$D$32="","",Rekap!$D$32) | H28: =IF(COUNT(D28:G28)<4,"",AVERAGE(D28:G28)/5*100)
A29: 13 | B29: =IF(Rekap!$B$33="","",Rekap!$B$33) | C29: =IF(Rekap!$D$33="","",Rekap!$D$33) | H29: =IF(COUNT(D29:G29)<4,"",AVERAGE(D29:G29)/5*100)
A30: 14 | B30: =IF(Rekap!$B$34="","",Rekap!$B$34) | C30: =IF(Rekap!$D$34="","",Rekap!$D$34) | H30: =IF(COUNT(D30:G30)<4,"",AVERAGE(D30:G30)/5*100)
A31: 15 | B31: =IF(Rekap!$B$35="","",Rekap!$B$35) | C31: =IF(Rekap!$D$35="","",Rekap!$D$35) | H31: =IF(COUNT(D31:G31)<4,"",AVERAGE(D31:G31)/5*100)
A32: 16 | B32: =IF(Rekap!$B$36="","",Rekap!$B$36) | C32: =IF(Rekap!$D$36="","",Rekap!$D$36) | H32: =IF(COUNT(D32:G32)<4,"",AVERAGE(D32:G32)/5*100)
A33: 17 | B33: =IF(Rekap!$B$37="","",Rekap!$B$37) | C33: =IF(Rekap!$D$37="","",Rekap!$D$37) | H33: =IF(COUNT(D33:G33)<4,"",AVERAGE(D33:G33)/5*100)
A34: 18 | B34: =IF(Rekap!$B$38="","",Rekap!$B$38) | C34: =IF(Rekap!$D$38="","",Rekap!$D$38) | H34: =IF(COUNT(D34:G34)<4,"",AVERAGE(D34:G34)/5*100)
A35: 19 | B35: =IF(Rekap!$B$39="","",Rekap!$B$39) | C35: =IF(Rekap!$D$39="","",Rekap!$D$39) | H35: =IF(COUNT(D35:G35)<4,"",AVERAGE(D35:G35)/5*100)
A36: 20 | B36: =IF(Rekap!$B$40="","",Rekap!$B$40) | C36: =IF(Rekap!$D$40="","",Rekap!$D$40) | H36: =IF(COUNT(D36:G36)<4,"",AVERAGE(D36:G36)/5*100)
A37: 21 | B37: =IF(Rekap!$B$41="","",Rekap!$B$41) | C37: =IF(Rekap!$D$41="","",Rekap!$D$41) | H37: =IF(COUNT(D37:G37)<4,"",AVERAGE(D37:G37)/5*100)
A38: 22 | B38: =IF(Rekap!$B$42="","",Rekap!$B$42) | C38: =IF(Rekap!$D$42="","",Rekap!$D$42) | H38: =IF(COUNT(D38:G38)<4,"",AVERAGE(D38:G38)/5*100)
A39: 23 | B39: =IF(Rekap!$B$43="","",Rekap!$B$43) | C39: =IF(Rekap!$D$43="","",Rekap!$D$43) | H39: =IF(COUNT(D39:G39)<4,"",AVERAGE(D39:G39)/5*100)
A40: 24 | B40: =IF(Rekap!$B$44="","",Rekap!$B$44) | C40: =IF(Rekap!$D$44="","",Rekap!$D$44) | H40: =IF(COUNT(D40:G40)<4,"",AVERAGE(D40:G40)/5*100)
A41: 25 | B41: =IF(Rekap!$B$45="","",Rekap!$B$45) | C41: =IF(Rekap!$D$45="","",Rekap!$D$45) | H41: =IF(COUNT(D41:G41)<4,"",AVERAGE(D41:G41)/5*100)
A42: 26 | B42: =IF(Rekap!$B$46="","",Rekap!$B$46) | C42: =IF(Rekap!$D$46="","",Rekap!$D$46) | H42: =IF(COUNT(D42:G42)<4,"",AVERAGE(D42:G42)/5*100)
...

Sheet Rekap
A1: Rekap Nilai - Pemrograman Web Lanjut (SIB Semester 5)
A2: Isi nama tim dan data mahasiswa di sini. Nilai tim dan nilai individu terisi otomatis dari sheet checkpoint masing-masing.
A4: Bobot Checkpoint | B4: Proposal | C4: Milestone 1 | D4: Milestone 2 | E4: Final | F4: Total
A5: Persentase | B5: 0.1 | C5: 0.25 | D5: 0.3 | E5: 0.35 | F5: =SUM(B5:E5)
A7: Porsi Nilai Akhir | B7: Porsi Nilai Tim | C7: Porsi Nilai Individu | D7: Total
A8: Persentase | B8: 0.3 | C8: 0.7 | D8: =SUM(B8:C8)
A10: Rekap Nilai Tim
A11: No | B11: Nama Tim | C11: Proposal | D11: Milestone 1 | E11: Milestone 2 | F11: Final | G11: Nilai Akhir Tim
A12: 1 | B12: Tim 1 | C12: =Proposal!H7 | D12: ='Milestone 1'!H7 | E12: ='Milestone 2'!H7 | F12: =Final!H7 | G12: =IF(COUNT(C12:F12)<4,"",SUMPRODUCT(C12:F12,B5:E5)/SUM(B5:E5))
A13: 2 | B13: Tim 2 | C13: =Proposal!H8 | D13: ='Milestone 1'!H8 | E13: ='Milestone 2'!H8 | F13: =Final!H8 | G13: =IF(COUNT(C13:F13)<4,"",SUMPRODUCT(C13:F13,B5:E5)/SUM(B5:E5))
A14: 3 | B14: Tim 3 | C14: =Proposal!H9 | D14: ='Milestone 1'!H9 | E14: ='Milestone 2'!H9 | F14: =Final!H9 | G14: =IF(COUNT(C14:F14)<4,"",SUMPRODUCT(C14:F14,B5:E5)/SUM(B5:E5))
A15: 4 | B15: Tim 4 | C15: =Proposal!H10 | D15: ='Milestone 1'!H10 | E15: ='Milestone 2'!H10 | F15: =Final!H10 | G15: =IF(COUNT(C15:F15)<4,"",SUMPRODUCT(C15:F15,B5:E5)/SUM(B5:E5))
A16: 5 | B16: Tim 5 | C16: =Proposal!H11 | D16: ='Milestone 1'!H11 | E16: ='Milestone 2'!H11 | F16: =Final!H11 | G16: =IF(COUNT(C16:F16)<4,"",SUMPRODUCT(C16:F16,B5:E5)/SUM(B5:E5))
A17: 6 | B17: Tim 6 | C17: =Proposal!H12 | D17: ='Milestone 1'!H12 | E17: ='Milestone 2'!H12 | F17: =Final!H12 | G17: =IF(COUNT(C17:F17)<4,"",SUMPRODUCT(C17:F17,B5:E5)/SUM(B5:E5))
A19: Rekap Nilai Mahasiswa
A20: No | B20: Nama Mahasiswa | C20: NIM | D20: Tim | E20: Individu Proposal | F20: Individu Milestone 1 | G20: Individu Milestone 2 | H20: Individu Final | I20: Nilai Individu Tertimbang | J20: Nilai Akhir Mahasiswa
A21: 1 | E21: =Proposal!H17 | F21: ='Milestone 1'!H17 | G21: ='Milestone 2'!H17 | H21: =Final!H17 | I21: =IF(COUNT(E21:H21)<4,"",SUMPRODUCT(E21:H21,B5:E5)/SUM(B5:E5)) | J21: =IFERROR(MIN(100,INDEX($G$12:$G$17,MATCH(D21,$B$12:$B$17,0))*$B$8+I21*$C$8),"")
A22: 2 | E22: =Proposal!H18 | F22: ='Milestone 1'!H18 | G22: ='Milestone 2'!H18 | H22: =Final!H18 | I22: =IF(COUNT(E22:H22)<4,"",SUMPRODUCT(E22:H22,B5:E5)/SUM(B5:E5)) | J22: =IFERROR(MIN(100,INDEX($G$12:$G$17,MATCH(D22,$B$12:$B$17,0))*$B$8+I22*$C$8),"")
A23: 3 | E23: =Proposal!H19 | F23: ='Milestone 1'!H19 | G23: ='Milestone 2'!H19 | H23: =Final!H19 | I23: =IF(COUNT(E23:H23)<4,"",SUMPRODUCT(E23:H23,B5:E5)/SUM(B5:E5)) | J23: =IFERROR(MIN(100,INDEX($G$12:$G$17,MATCH(D23,$B$12:$B$17,0))*$B$8+I23*$C$8),"")
A24: 4 | E24: =Proposal!H20 | F24: ='Milestone 1'!H20 | G24: ='Milestone 2'!H20 | H24: =Final!H20 | I24: =IF(COUNT(E24:H24)<4,"",SUMPRODUCT(E24:H24,B5:E5)/SUM(B5:E5)) | J24: =IFERROR(MIN(100,INDEX($G$12:$G$17,MATCH(D24,$B$12:$B$17,0))*$B$8+I24*$C$8),"")
A25: 5 | E25: =Proposal!H21 | F25: ='Milestone 1'!H21 | G25: ='Milestone 2'!H21 | H25: =Final!H21 | I25: =IF(COUNT(E25:H25)<4,"",SUMPRODUCT(E25:H25,B5:E5)/SUM(B5:E5)) | J25: =IFERROR(MIN(100,INDEX($G$12:$G$17,MATCH(D25,$B$12:$B$17,0))*$B$8+I25*$C$8),"")
A26: 6 | E26: =Proposal!H22 | F26: ='Milestone 1'!H22 | G26: ='Milestone 2'!H22 | H26: =Final!H22 | I26: =IF(COUNT(E26:H26)<4,"",SUMPRODUCT(E26:H26,B5:E5)/SUM(B5:E5)) | J26: =IFERROR(MIN(100,INDEX($G$12:$G$17,MATCH(D26,$B$12:$B$17,0))*$B$8+I26*$C$8),"")
A27: 7 | E27: =Proposal!H23 | F27: ='Milestone 1'!H23 | G27: ='Milestone 2'!H23 | H27: =Final!H23 | I27: =IF(COUNT(E27:H27)<4,"",SUMPRODUCT(E27:H27,B5:E5)/SUM(B5:E5)) | J27: =IFERROR(MIN(100,INDEX($G$12:$G$17,MATCH(D27,$B$12:$B$17,0))*$B$8+I27*$C$8),"")
A28: 8 | E28: =Proposal!H24 | F28: ='Milestone 1'!H24 | G28: ='Milestone 2'!H24 | H28: =Final!H24 | I28: =IF(COUNT(E28:H28)<4,"",SUMPRODUCT(E28:H28,B5:E5)/SUM(B5:E5)) | J28: =IFERROR(MIN(100,INDEX($G$12:$G$17,MATCH(D28,$B$12:$B$17,0))*$B$8+I28*$C$8),"")
A29: 9 | E29: =Proposal!H25 | F29: ='Milestone 1'!H25 | G29: ='Milestone 2'!H25 | H29: =Final!H25 | I29: =IF(COUNT(E29:H29)<4,"",SUMPRODUCT(E29:H29,B5:E5)/SUM(B5:E5)) | J29: =IFERROR(MIN(100,INDEX($G$12:$G$17,MATCH(D29,$B$12:$B$17,0))*$B$8+I29*$C$8),"")
A30: 10 | E30: =Proposal!H26 | F30: ='Milestone 1'!H26 | G30: ='Milestone 2'!H26 | H30: =Final!H26 | I30: =IF(COUNT(E30:H30)<4,"",SUMPRODUCT(E30:H30,B5:E5)/SUM(B5:E5)) | J30: =IFERROR(MIN(100,INDEX($G$12:$G$17,MATCH(D30,$B$12:$B$17,0))*$B$8+I30*$C$8),"")
A31: 11 | E31: =Proposal!H27 | F31: ='Milestone 1'!H27 | G31: ='Milestone 2'!H27 | H31: =Final!H27 | I31: =IF(COUNT(E31:H31)<4,"",SUMPRODUCT(E31:H31,B5:E5)/SUM(B5:E5)) | J31: =IFERROR(MIN(100,INDEX($G$12:$G$17,MATCH(D31,$B$12:$B$17,0))*$B$8+I31*$C$8),"")
A32: 12 | E32: =Proposal!H28 | F32: ='Milestone 1'!H28 | G32: ='Milestone 2'!H28 | H32: =Final!H28 | I32: =IF(COUNT(E32:H32)<4,"",SUMPRODUCT(E32:H32,B5:E5)/SUM(B5:E5)) | J32: =IFERROR(MIN(100,INDEX($G$12:$G$17,MATCH(D32,$B$12:$B$17,0))*$B$8+I32*$C$8),"")
A33: 13 | E33: =Proposal!H29 | F33: ='Milestone 1'!H29 | G33: ='Milestone 2'!H29 | H33: =Final!H29 | I33: =IF(COUNT(E33:H33)<4,"",SUMPRODUCT(E33:H33,B5:E5)/SUM(B5:E5)) | J33: =IFERROR(MIN(100,INDEX($G$12:$G$17,MATCH(D33,$B$12:$B$17,0))*$B$8+I33*$C$8),"")
A34: 14 | E34: =Proposal!H30 | F34: ='Milestone 1'!H30 | G34: ='Milestone 2'!H30 | H34: =Final!H30 | I34: =IF(COUNT(E34:H34)<4,"",SUMPRODUCT(E34:H34,B5:E5)/SUM(B5:E5)) | J34: =IFERROR(MIN(100,INDEX($G$12:$G$17,MATCH(D34,$B$12:$B$17,0))*$B$8+I34*$C$8),"")
A35: 15 | E35: =Proposal!H31 | F35: ='Milestone 1'!H31 | G35: ='Milestone 2'!H31 | H35: =Final!H31 | I35: =IF(COUNT(E35:H35)<4,"",SUMPRODUCT(E35:H35,B5:E5)/SUM(B5:E5)) | J35: =IFERROR(MIN(100,INDEX($G$12:$G$17,MATCH(D35,$B$12:$B$17,0))*$B$8+I35*$C$8),"")
A36: 16 | E36: =Proposal!H32 | F36: ='Milestone 1'!H32 | G36: ='Milestone 2'!H32 | H36: =Final!H32 | I36: =IF(COUNT(E36:H36)<4,"",SUMPRODUCT(E36:H36,B5:E5)/SUM(B5:E5)) | J36: =IFERROR(MIN(100,INDEX($G$12:$G$17,MATCH(D36,$B$12:$B$17,0))*$B$8+I36*$C$8),"")
A37: 17 | E37: =Proposal!H33 | F37: ='Milestone 1'!H33 | G37: ='Milestone 2'!H33 | H37: =Final!H33 | I37: =IF(COUNT(E37:H37)<4,"",SUMPRODUCT(E37:H37,B5:E5)/SUM(B5:E5)) | J37: =IFERROR(MIN(100,INDEX($G$12:$G$17,MATCH(D37,$B$12:$B$17,0))*$B$8+I37*$C$8),"")
A38: 18 | E38: =Proposal!H34 | F38: ='Milestone 1'!H34 | G38: ='Milestone 2'!H34 | H38: =Final!H34 | I38: =IF(COUNT(E38:H38)<4,"",SUMPRODUCT(E38:H38,B5:E5)/SUM(B5:E5)) | J38: =IFERROR(MIN(100,INDEX($G$12:$G$17,MATCH(D38,$B$12:$B$17,0))*$B$8+I38*$C$8),"")
A39: 19 | E39: =Proposal!H35 | F39: ='Milestone 1'!H35 | G39: ='Milestone 2'!H35 | H39: =Final!H35 | I39: =IF(COUNT(E39:H39)<4,"",SUMPRODUCT(E39:H39,B5:E5)/SUM(B5:E5)) | J39: =IFERROR(MIN(100,INDEX($G$12:$G$17,MATCH(D39,$B$12:$B$17,0))*$B$8+I39*$C$8),"")
A40: 20 | E40: =Proposal!H36 | F40: ='Milestone 1'!H36 | G40: ='Milestone 2'!H36 | H40: =Final!H36 | I40: =IF(COUNT(E40:H40)<4,"",SUMPRODUCT(E40:H40,B5:E5)/SUM(B5:E5)) | J40: =IFERROR(MIN(100,INDEX($G$12:$G$17,MATCH(D40,$B$12:$B$17,0))*$B$8+I40*$C$8),"")
A41: 21 | E41: =Proposal!H37 | F41: ='Milestone 1'!H37 | G41: ='Milestone 2'!H37 | H41: =Final!H37 | I41: =IF(COUNT(E41:H41)<4,"",SUMPRODUCT(E41:H41,B5:E5)/SUM(B5:E5)) | J41: =IFERROR(MIN(100,INDEX($G$12:$G$17,MATCH(D41,$B$12:$B$17,0))*$B$8+I41*$C$8),"")
A42: 22 | E42: =Proposal!H38 | F42: ='Milestone 1'!H38 | G42: ='Milestone 2'!H38 | H42: =Final!H38 | I42: =IF(COUNT(E42:H42)<4,"",SUMPRODUCT(E42:H42,B5:E5)/SUM(B5:E5)) | J42: =IFERROR(MIN(100,INDEX($G$12:$G$17,MATCH(D42,$B$12:$B$17,0))*$B$8+I42*$C$8),"")
A43: 23 | E43: =Proposal!H39 | F43: ='Milestone 1'!H39 | G43: ='Milestone 2'!H39 | H43: =Final!H39 | I43: =IF(COUNT(E43:H43)<4,"",SUMPRODUCT(E43:H43,B5:E5)/SUM(B5:E5)) | J43: =IFERROR(MIN(100,INDEX($G$12:$G$17,MATCH(D43,$B$12:$B$17,0))*$B$8+I43*$C$8),"")
A44: 24 | E44: =Proposal!H40 | F44: ='Milestone 1'!H40 | G44: ='Milestone 2'!H40 | H44: =Final!H40 | I44: =IF(COUNT(E44:H44)<4,"",SUMPRODUCT(E44:H44,B5:E5)/SUM(B5:E5)) | J44: =IFERROR(MIN(100,INDEX($G$12:$G$17,MATCH(D44,$B$12:$B$17,0))*$B$8+I44*$C$8),"")
...
